Workbook

Sheet Summary
A1: House No. 79/K, WAPDA City Faisalabad - Grey Structure MATERIAL Estimate, Rev 1
A2: Material only (no labour). Quantities from the structural and working drawings and the owner's Final Decisions Register. Rates Oct 2026.
A4: Total material cost (PKR) | B4: =Totals!L86 -> 9189795
A5: Covered area (sft) | B5: =Totals!L87 -> 4104
A6: Cost per sft of covered area (PKR) | B6: =Totals!L88 -> 2239.2288
A8: Main material | B8: Purchase qty | C8: Unit | D8: Cost (PKR)
A9: Cement OPC 50 kg | B9: =Totals!I5 -> 1544 | C9: =Totals!C5 -> bag | D9: =Totals!L5 -> 2408640
A10: Bricks first class | B10: =Totals!I6 -> 133000 | C10: =Totals!C6 -> nos | D10: =Totals!L6 -> 2128000
A11: Steel #3 (10 mm) | B11: =Totals!I8 -> 3940 | C11: =Totals!C8 -> kg | D11: =Totals!L8 -> 1032280
A12: Steel #4 (12 mm) | B12: =Totals!I9 -> 2260 | C12: =Totals!C9 -> kg | D12: =Totals!L9 -> 592120
A13: Steel #6 (20 mm) | B13: =Totals!I10 -> 1020 | C13: =Totals!C10 -> kg | D13: =Totals!L10 -> 267240
A14: Steel #2 (6 mm) | B14: =Totals!I7 -> 170 | C14: =Totals!C7 -> kg | D14: =Totals!L7 -> 45900
A15: Binding wire | B15: =Totals!I11 -> 75 | C15: =Totals!C11 -> kg | D15: =Totals!L11 -> 30000
A16: Crush ¾" Sargodha | B16: =Totals!I14 -> 4000 | C16: =Totals!C14 -> cft | D16: =Totals!L14 -> 440000
A17: Chenab sand | B17: =Totals!I12 -> 2550 | C17: =Totals!C12 -> cft | D17: =Totals!L12 -> 165750
A18: Ravi sand | B18: =Totals!I13 -> 5400 | C18: =Totals!C13 -> cft | D18: =Totals!L13 -> 216000
A19: Khangar (stone ballast) | B19: =Totals!I15 -> 700 | C19: =Totals!C15 -> cft | D19: =Totals!L15 -> 63000
A20: Earth to buy | B20: =Totals!I16 -> 4200 | C20: =Totals!C16 -> cft | D20: =Totals!L16 -> 105000
A21: Hot bitumen | B21: =Totals!I18 -> 500 | C21: =Totals!C18 -> kg | D21: =Totals!L18 -> 140000
A22: Roof membrane 4 mm | B22: =Totals!I21 -> 230 | C22: =Totals!C21 -> m2 | D22: =Totals!L21 -> 161000
A23: Bhatta roof tiles | B23: =Totals!I27 -> 5300 | C23: =Totals!C27 -> nos | D23: =Totals!L27 -> 106000
A25: Sheets: BOQ (lines, live formulas) | Totals (purchase) | Rates (edit yellow cells) | Stages | Steel | Levels
A26: Inputs: yellow cells with blue text on the Rates sheet (rate, wastage) and the covered area on Totals.

Sheet Rates
A1: Rates and wastage - edit the yellow cells (blue text = input)
A2: Rates in PKR per unit, Faisalabad, October 2026. "estimated" = no published 2026 figure found. Wastage per Register K2 (lower-middle of normal range).
A4: Key | B4: Material | C4: Unit | D4: Wastage % | E4: Rate (PKR / unit) | F4: Buying unit | G4: Unit size | H4: Rate date | I4: Source / note | J4: Group
A5: CEM | B5: Cement OPC, 50 kg bag (Lucky / Bestway / Maple Leaf) | C5: bag | D5: 0.03 | E5: 1560 | F5: bag | G5: 1 | H5: Sep 2026 | I5: ARY News "Cement Price in Pakistan Today", 15 Aug 2026 (Rs 1,500-1,610/bag); Sep 2026 brand list (Lucky 1,500-1,540, Bestway 1,430-1,570, Maple Leaf 1,570) - Faisalabad estimate | J5: Cement
A6: BRK | B6: Bricks, first class (awwal), 9" x 4½" x 3" | C6: nos | D6: 0.05 | E6: 16 | F6: 1,000 bricks | G6: 1000 | H6: Jan-Oct 2026 | I6: The News (PBS) Jan 2026: Lahore Rs 17,463/1,000; Pak Observer: Faisalabad DC-fixed A-class Rs 12,000/1,000 - market estimate Rs 16,000/1,000 | J6: Bricks
A7: ST2 | B7: Steel Grade 60 deformed, #2 (6 mm) rings | C7: kg | D7: 0.04 | E7: 270 | F7: 10 kg | G7: 10 | H7: Sep 2026 | I7: Grade 60 Rs 258-265/kg (Daily Ausaf 19 Sep 2026 / Daily Qudrat 26 Sep 2026 price reports) + small-bar premium (estimated) | J7: Steel
A8: ST3 | B8: Steel Grade 60 deformed, #3 (10 mm) (Amreli / Mughal / FF Steel) | C8: kg | D8: 0.04 | E8: 262 | F8: 10 kg | G8: 10 | H8: Sep 2026 | I8: Grade 60 Rs 258-265/kg (Daily Ausaf 19 Sep 2026 / Daily Qudrat 26 Sep 2026 price reports) | J8: Steel
A9: ST4 | B9: Steel Grade 60 deformed, #4 (12 mm) | C9: kg | D9: 0.04 | E9: 262 | F9: 10 kg | G9: 10 | H9: Sep 2026 | I9: as #3 | J9: Steel
A10: ST6 | B10: Steel Grade 60 deformed, #6 (20 mm) | C10: kg | D10: 0.04 | E10: 262 | F10: 10 kg | G10: 10 | H10: Sep 2026 | I10: as #3 | J10: Steel
A11: BWIRE | B11: Binding wire, annealed 18 gauge | C11: kg | D11: 0 | E11: 400 | F11: 5 kg | G11: 5 | H11: Oct 2026 | I11: estimated | J11: Steel
A12: SNDC | B12: Chenab sand (concrete, screed) | C12: cft | D12: 0.08 | E12: 65 | F12: 50 cft | G12: 50 | H12: Jul 2026 | I12: toolsfluent.com Pakistan construction cost guide 2026: river sand Rs 65/cft | J12: Sand
A13: SNDM | B13: Ravi sand (mortar, plaster, blinding, fill) | C13: cft | D13: 0.08 | E13: 40 | F13: 50 cft | G13: 50 | H13: Oct 2026 | I13: estimated (about 60% of Chenab sand rate) | J13: Sand
A14: CRS | B14: Crush ¾" down, Sargodha (bajri) | C14: cft | D14: 0.05 | E14: 110 | F14: 50 cft | G14: 50 | H14: Jul 2026 | I14: toolsfluent.com 2026 guide: crush Rs 105/cft + delivery to Faisalabad (estimated) | J14: Crush
A15: KHG | B15: Stone ballast (khangar) 1½"-2½" | C15: cft | D15: 0.05 | E15: 90 | F15: 50 cft | G15: 50 | H15: Oct 2026 | I15: estimated | J15: Stone ballast
A16: EARTH | B16: Earth (mitti) for filling, delivered | C16: cft | D16: 0 | E16: 25 | F16: 50 cft | G16: 50 | H16: Oct 2026 | I16: estimated (~Rs 2,500 per 100-cft tractor-trolley); 20% compaction already in quantity | J16: Earth
... A84: JBOLT | B84: M12 x 250 mm galvanised J-bolt with nut and washer | C84: nos | D84: 0 | E84: 250 | F84: nos | G84: 1 | H84: Oct 2026 | I84: estimated | J84: Solar plinths
A86: Legend: yellow cells with blue text are inputs; all other numbers in this workbook are formulas.
A87: Example: to price cement at Rs 1,600 per bag, type 1600 in the cement row of column E; every sheet updates.

Sheet BOQ
A1: House 79/K - Grey structure MATERIAL BOQ, Revision 1 (by construction stage)
A2: One row per material of each BOQ line. Net qty = measured quantity; Gross = Net x (1 + wastage); Amount = Gross x Rate. Wastage and rates come from the Rates sheet. Purchase rounding to buying units is on the Totals sheet.
A4: Stage | B4: Stage name | C4: Item | D4: Location | E4: Description | F4: Dimensions | G4: Quantity working | H4: Item qty | I4: Item unit | J4: Register | K4: Member group | L4: Earth tag | M4: Mat. key | N4: Material | O4: Net qty | P4: Unit | Q4: Wastage % | R4: Gross qty | S4: Rate (PKR) | T4: Amount (PKR) | U4: Loads (trolleys)
A5: S1 | B5: Levels and layout | C5: 1.1 | D5: Whole plot | E5: Level survey and setting out (no materials) | F5: Road crown = ±0; NSL = -1'-6"; FFL +2'-9"; porches +1'-3"; lawn +1'-2" | G5: Take levels at the 4 corners and centre before digging; set out walls from sheets 04/06 (architect's dimensions govern) | H5: 1 | I5: job | J5: A1, A3 | T5: 0
A6: S2 | B6: Excavation | C6: 2.1 | D6: All house walls | E6: Excavation of wall trenches to PCC bottom, 2'-6" below NSL (4'-0" below road) | F6: PCC footprint 927.4 sft (3'-0" under 9" walls, 2'-6" under 4½" walls; union of all walls, eccentric on property line) | G6: 927.4 sft x 2.50 ft x 1.10 working space | H6: 2550.366 | I6: cft | J6: A1, A3, C1, C2, C4 | L6: EXC | T6: 0
A7: S2 | B7: Excavation | C7: 2.2 | D7: Car-porch front corner | E7: Excavation for isolated column footing | F7: 3'-6" x 3'-6" x 2'-6" deep | G7: 3.5 x 3.5 x 2.5 x 1.10 | H7: 33.688 | I7: cft | J7: C5 | L7: EXC | T7: 0
A8: S2 | B8: Excavation | C8: 2.3 | D8: Porch, lawn and gate edges | E8: Excavation for edge / retaining walls (section D-D), PCC bottom 2'-3" below NSL | F8: 42.7 ft x 2'-6" x 2'-3" | G8: 42.71 x 2.5 x 2.25 x 1.10 | H8: 264.268 | I8: cft | J8: C6 | L8: EXC | T8: 0
A9: S3 | B9: Anti-termite treatment | C9: 3.1 | D9: House trenches | E9: Termiticide on trench bottoms and sides, before PCC | F9: bottoms 927 sft + sides 2 x 370.7 ft x 2'-6" | G9: 2,781 sft = 258.4 m2 x 5 L/m2 = 1,292 L emulsion; ÷ 200 | H9: 6.459 | I9: L | J9: B1 | M9: TERM | N9: =IFERROR(INDEX(Rates!$B$5:$B$84,MATCH(M9,Rates!$A$5:$A$84,0)),"") -> Termiticide: bifenthrin 10% EC (1 L makes 200 L emulsion) | O9: 6.459 | P9: =IFERROR(INDEX(Rates!$C$5:$C$84,MATCH(M9,Rates!$A$5:$A$84,0)),"") -> L | Q9: =IFERROR(INDEX(Rates!$D$5:$D$84,MATCH(M9,Rates!$A$5:$A$84,0)),0) -> 0.05 | R9: =O9*(1+Q9) -> 6.78195 | S9: =IFERROR(INDEX(Rates!$E$5:$E$84,MATCH(M9,Rates!$A$5:$A$84,0)),0) -> 3500 | T9: =R9*S9 -> 23736.825 | U9: =IF(M9="BRK",R9/2000,IF(OR(M9="SNDC",M9="SNDM",M9="CRS",M9="KHG",M9="EARTH"),R9/100,""))
A10: S3 | B10: Anti-termite treatment | C10: 3.2 | D10: House floor + both car porches | E10: Termiticide on top of compacted plinth filling, before khangar | F10: rooms 1,363 + front porch 308 + rear porch 143 sft | G10: 1,814 sft = 168.5 m2 x 5 L/m2 = 843 L emulsion; ÷ 200 | H10: 4.213 | I10: L | J10: B1 | M10: TERM | N10: =IFERROR(INDEX(Rates!$B$5:$B$84,MATCH(M10,Rates!$A$5:$A$84,0)),"") -> Termiticide: bifenthrin 10% EC (1 L makes 200 L emulsion) | O10: 4.2127 | P10: =IFERROR(INDEX(Rates!$C$5:$C$84,MATCH(M10,Rates!$A$5:$A$84,0)),"") -> L | Q10: =IFERROR(INDEX(Rates!$D$5:$D$84,MATCH(M10,Rates!$A$5:$A$84,0)),0) -> 0.05 | R10: =O10*(1+Q10) -> 4.423335 | S10: =IFERROR(INDEX(Rates!$E$5:$E$84,MATCH(M10,Rates!$A$5:$A$84,0)),0) -> 3500 | T10: =R10*S10 -> 15481.673 | U10: =IF(M10="BRK",R10/2000,IF(OR(M10="SNDC",M10="SNDM",M10="CRS",M10="KHG",M10="EARTH"),R10/100,""))
A11: S3 | B11: Anti-termite treatment | C11: 3.3 | D11: House perimeter | E11: Termiticide in soil along outside of plinth walls, after back-filling | F11: outer walls 173.7 ft | G11: 52.9 m x 2.25 L/m = 119 L emulsion; ÷ 200 | H11: 0.596 | I11: L | J11: B1 | M11: TERM | N11: =IFERROR(INDEX(Rates!$B$5:$B$84,MATCH(M11,Rates!$A$5:$A$84,0)),"") -> Termiticide: bifenthrin 10% EC (1 L makes 200 L emulsion) | O11: 0.5956 | P11: =IFERROR(INDEX(Rates!$C$5:$C$84,MATCH(M11,Rates!$A$5:$A$84,0)),"") -> L | Q11: =IFERROR(INDEX(Rates!$D$5:$D$84,MATCH(M11,Rates!$A$5:$A$84,0)),0) -> 0.05 | R11: =O11*(1+Q11) -> 0.62538 | S11: =IFERROR(INDEX(Rates!$E$5:$E$84,MATCH(M11,Rates!$A$5:$A$84,0)),0) -> 3500 | T11: =R11*S11 -> 2188.83 | U11: =IF(M11="BRK",R11/2000,IF(OR(M11="SNDC",M11="SNDM",M11="CRS",M11="KHG",M11="EARTH"),R11/100,""))
A12: S4 | B12: Foundations | C12: 4.1 | D12: All house walls | E12: PCC 1:4:8, 3" thick, under brick footings (sheet 05 widths 3'-0" / 2'-6") | F12: 927.4 sft x 3" | G12: 927.4 x 0.25 | H12: 231.851 | I12: cft | J12: C1, C3 | K12: Foundations | M12: CEM | N12: =IFERROR(INDEX(Rates!$B$5:$B$84,MATCH(M12,Rates!$A$5:$A$84,0)),"") -> Cement OPC, 50 kg bag (Lucky / Bestway / Maple Leaf) | O12: 22.4004 | P12: =IFERROR(INDEX(Rates!$C$5:$C$84,MATCH(M12,Rates!$A$5:$A$84,0)),"") -> bag | Q12: =IFERROR(INDEX(Rates!$D$5:$D$84,MATCH(M12,Rates!$A$5:$A$84,0)),0) -> 0.03 | R12: =O12*(1+Q12) -> 23.072412 | S12: =IFERROR(INDEX(Rates!$E$5:$E$84,MATCH(M12,Rates!$A$5:$A$84,0)),0) -> 1560 | T12: =R12*S12 -> 35992.963 | U12: =IF(M12="BRK",R12/2000,IF(OR(M12="SNDC",M12="SNDM",M12="CRS",M12="KHG",M12="EARTH"),R12/100,""))
A13: S4 | B13: Foundations | C13: 4.1 | J13: C1, C3 | K13: Foundations | M13: SNDC | N13: =IFERROR(INDEX(Rates!$B$5:$B$84,MATCH(M13,Rates!$A$5:$A$84,0)),"") -> Chenab sand (concrete, screed) | O13: 112.0021 | P13: =IFERROR(INDEX(Rates!$C$5:$C$84,MATCH(M13,Rates!$A$5:$A$84,0)),"") -> cft | Q13: =IFERROR(INDEX(Rates!$D$5:$D$84,MATCH(M13,Rates!$A$5:$A$84,0)),0) -> 0.08 | R13: =O13*(1+Q13) -> 120.96227 | S13: =IFERROR(INDEX(Rates!$E$5:$E$84,MATCH(M13,Rates!$A$5:$A$84,0)),0) -> 65 | T13: =R13*S13 -> 7862.5474 | U13: =IF(M13="BRK",R13/2000,IF(OR(M13="SNDC",M13="SNDM",M13="CRS",M13="KHG",M13="EARTH"),R13/100,"")) -> 1.2096227
A14: S4 | B14: Foundations | C14: 4.1 | J14: C1, C3 | K14: Foundations | M14: CRS | N14: =IFERROR(INDEX(Rates!$B$5:$B$84,MATCH(M14,Rates!$A$5:$A$84,0)),"") -> Crush ¾" down, Sargodha (bajri) | O14: 224.0042 | P14: =IFERROR(INDEX(Rates!$C$5:$C$84,MATCH(M14,Rates!$A$5:$A$84,0)),"") -> cft | Q14: =IFERROR(INDEX(Rates!$D$5:$D$84,MATCH(M14,Rates!$A$5:$A$84,0)),0) -> 0.05 | R14: =O14*(1+Q14) -> 235.20441 | S14: =IFERROR(INDEX(Rates!$E$5:$E$84,MATCH(M14,Rates!$A$5:$A$84,0)),0) -> 110 | T14: =R14*S14 -> 25872.485 | U14: =IF(M14="BRK",R14/2000,IF(OR(M14="SNDC",M14="SNDM",M14="CRS",M14="KHG",M14="EARTH"),R14/100,"")) -> 2.3520441
A15: S4 | B15: Foundations | C15: 4.2 | D15: All house walls | E15: Brick footing in 1:6: steps 27" / 22½" / 18" under 9" walls, 22½" / 18" / 13½" under 4½" walls, 6" each | F15: union plan areas 719.8 + 604.8 + 485.2 sft x 6" | G15: (719.8 + 604.8 + 485.2) x 0.5 | H15: 904.913 | I15: cft | J15: C1, C3 | M15: CEM | N15: =IFERROR(INDEX(Rates!$B$5:$B$84,MATCH(M15,Rates!$A$5:$A$84,0)),"") -> Cement OPC, 50 kg bag (Lucky / Bestway / Maple Leaf) | O15: 41.264 | P15: =IFERROR(INDEX(Rates!$C$5:$C$84,MATCH(M15,Rates!$A$5:$A$84,0)),"") -> bag | Q15: =IFERROR(INDEX(Rates!$D$5:$D$84,MATCH(M15,Rates!$A$5:$A$84,0)),0) -> 0.03 | R15: =O15*(1+Q15) -> 42.50192 | S15: =IFERROR(INDEX(Rates!$E$5:$E$84,MATCH(M15,Rates!$A$5:$A$84,0)),0) -> 1560 | T15: =R15*S15 -> 66302.995 | U15: =IF(M15="BRK",R15/2000,IF(OR(M15="SNDC",M15="SNDM",M15="CRS",M15="KHG",M15="EARTH"),R15/100,""))
A16: S4 | B16: Foundations | C16: 4.2 | J16: C1, C3 | M16: SNDM | N16: =IFERROR(INDEX(Rates!$B$5:$B$84,MATCH(M16,Rates!$A$5:$A$84,0)),"") -> Ravi sand (mortar, plaster, blinding, fill) | O16: 309.4803 | P16: =IFERROR(INDEX(Rates!$C$5:$C$84,MATCH(M16,Rates!$A$5:$A$84,0)),"") -> cft | Q16: =IFERROR(INDEX(Rates!$D$5:$D$84,MATCH(M16,Rates!$A$5:$A$84,0)),0) -> 0.08 | R16: =O16*(1+Q16) -> 334.23872 | S16: =IFERROR(INDEX(Rates!$E$5:$E$84,MATCH(M16,Rates!$A$5:$A$84,0)),0) -> 40 | T16: =R16*S16 -> 13369.549 | U16: =IF(M16="BRK",R16/2000,IF(OR(M16="SNDC",M16="SNDM",M16="CRS",M16="KHG",M16="EARTH"),R16/100,"")) -> 3.3423872
A17: S4 | B17: Foundations | C17: 4.2 | J17: C1, C3 | M17: BRK | N17: =IFERROR(INDEX(Rates!$B$5:$B$84,MATCH(M17,Rates!$A$5:$A$84,0)),"") -> Bricks, first class (awwal), 9" x 4½" x 3" | O17: 12216.326 | P17: =IFERROR(INDEX(Rates!$C$5:$C$84,MATCH(M17,Rates!$A$5:$A$84,0)),"") -> nos | Q17: =IFERROR(INDEX(Rates!$D$5:$D$84,MATCH(M17,Rates!$A$5:$A$84,0)),0) -> 0.05 | R17: =O17*(1+Q17) -> 12827.143 | S17: =IFERROR(INDEX(Rates!$E$5:$E$84,MATCH(M17,Rates!$A$5:$A$84,0)),0) -> 16 | T17: =R17*S17 -> 205234.28 | U17: =IF(M17="BRK",R17/2000,IF(OR(M17="SNDC",M17="SNDM",M17="CRS",M17="KHG",M17="EARTH"),R17/100,"")) -> 6.4135713
A18: S4 | B18: Foundations | C18: 4.3 | D18: All house walls | E18: Foundation wall in 1:6 from top of steps (-2'-3") to road level: 13½" under 9" walls, 9" under 4½" walls | F18: plan 361.0 sft x 2'-3" | G18: 361.0 x 2.25 | H18: 812.334 | I18: cft | J18: C1 | M18: CEM | N18: =IFERROR(INDEX(Rates!$B$5:$B$84,MATCH(M18,Rates!$A$5:$A$84,0)),"") -> Cement OPC, 50 kg bag (Lucky / Bestway / Maple Leaf) | O18: 37.0424 | P18: =IFERROR(INDEX(Rates!$C$5:$C$84,MATCH(M18,Rates!$A$5:$A$84,0)),"") -> bag | Q18: =IFERROR(INDEX(Rates!$D$5:$D$84,MATCH(M18,Rates!$A$5:$A$84,0)),0) -> 0.03 | R18: =O18*(1+Q18) -> 38.153672 | S18: =IFERROR(INDEX(Rates!$E$5:$E$84,MATCH(M18,Rates!$A$5:$A$84,0)),0) -> 1560 | T18: =R18*S18 -> 59519.728 | U18: =IF(M18="BRK",R18/2000,IF(OR(M18="SNDC",M18="SNDM",M18="CRS",M18="KHG",M18="EARTH"),R18/100,""))
A19: S4 | B19: Foundations | C19: 4.3 | J19: C1 | M19: SNDM | N19: =IFERROR(INDEX(Rates!$B$5:$B$84,MATCH(M19,Rates!$A$5:$A$84,0)),"") -> Ravi sand (mortar, plaster, blinding, fill) | O19: 277.8183 | P19: =IFERROR(INDEX(Rates!$C$5:$C$84,MATCH(M19,Rates!$A$5:$A$84,0)),"") -> cft | Q19: =IFERROR(INDEX(Rates!$D$5:$D$84,MATCH(M19,Rates!$A$5:$A$84,0)),0) -> 0.08 | R19: =O19*(1+Q19) -> 300.04376 | S19: =IFERROR(INDEX(Rates!$E$5:$E$84,MATCH(M19,Rates!$A$5:$A$84,0)),0) -> 40 | T19: =R19*S19 -> 12001.751 | U19: =IF(M19="BRK",R19/2000,IF(OR(M19="SNDC",M19="SNDM",M19="CRS",M19="KHG",M19="EARTH"),R19/100,"")) -> 3.0004376
A20: S4 | B20: Foundations | C20: 4.3 | J20: C1 | M20: BRK | N20: =IFERROR(INDEX(Rates!$B$5:$B$84,MATCH(M20,Rates!$A$5:$A$84,0)),"") -> Bricks, first class (awwal), 9" x 4½" x 3" | O20: 10966.512 | P20: =IFERROR(INDEX(Rates!$C$5:$C$84,MATCH(M20,Rates!$A$5:$A$84,0)),"") -> nos | Q20: =IFERROR(INDEX(Rates!$D$5:$D$84,MATCH(M20,Rates!$A$5:$A$84,0)),0) -> 0.05 | R20: =O20*(1+Q20) -> 11514.838 | S20: =IFERROR(INDEX(Rates!$E$5:$E$84,MATCH(M20,Rates!$A$5:$A$84,0)),0) -> 16 | T20: =R20*S20 -> 184237.41 | U20: =IF(M20="BRK",R20/2000,IF(OR(M20="SNDC",M20="SNDM",M20="CRS",M20="KHG",M20="EARTH"),R20/100,"")) -> 5.757419
A21: S4 | B21: Foundations | C21: 4.4 | D21: All house walls | E21: Plinth wall 9" in 1:6 from road level to underside of plinth beam (+1'-10½") | F21: plan 270.6 sft x 1'-10½" | G21: 270.6 x 1.875 | H21: 507.316 | I21: cft | J21: C1, B4 | M21: CEM | N21: =IFERROR(INDEX(Rates!$B$5:$B$84,MATCH(M21,Rates!$A$5:$A$84,0)),"") -> Cement OPC, 50 kg bag (Lucky / Bestway / Maple Leaf) | O21: 23.1336 | P21: =IFERROR(INDEX(Rates!$C$5:$C$84,MATCH(M21,Rates!$A$5:$A$84,0)),"") -> bag | Q21: =IFERROR(INDEX(Rates!$D$5:$D$84,MATCH(M21,Rates!$A$5:$A$84,0)),0) -> 0.03 | R21: =O21*(1+Q21) -> 23.827608 | S21: =IFERROR(INDEX(Rates!$E$5:$E$84,MATCH(M21,Rates!$A$5:$A$84,0)),0) -> 1560 | T21: =R21*S21 -> 37171.068 | U21: =IF(M21="BRK",R21/2000,IF(OR(M21="SNDC",M21="SNDM",M21="CRS",M21="KHG",M21="EARTH"),R21/100,""))
A22: S4 | B22: Foundations | C22: 4.4 | J22: C1, B4 | M22: SNDM | N22: =IFERROR(INDEX(Rates!$B$5:$B$84,MATCH(M22,Rates!$A$5:$A$84,0)),"") -> Ravi sand (mortar, plaster, blinding, fill) | O22: 173.5021 | P22: =IFERROR(INDEX(Rates!$C$5:$C$84,MATCH(M22,Rates!$A$5:$A$84,0)),"") -> cft | Q22: =IFERROR(INDEX(Rates!$D$5:$D$84,MATCH(M22,Rates!$A$5:$A$84,0)),0) -> 0.08 | R22: =O22*(1+Q22) -> 187.38227 | S22: =IFERROR(INDEX(Rates!$E$5:$E$84,MATCH(M22,Rates!$A$5:$A$84,0)),0) -> 40 | T22: =R22*S22 -> 7495.2907 | U22: =IF(M22="BRK",R22/2000,IF(OR(M22="SNDC",M22="SNDM",M22="CRS",M22="KHG",M22="EARTH"),R22/100,"")) -> 1.8738227
A23: S4 | B23: Foundations | C23: 4.4 | J23: C1, B4 | M23: BRK | N23: =IFERROR(INDEX(Rates!$B$5:$B$84,MATCH(M23,Rates!$A$5:$A$84,0)),"") -> Bricks, first class (awwal), 9" x 4½" x 3" | O23: 6848.7662 | P23: =IFERROR(INDEX(Rates!$C$5:$C$84,MATCH(M23,Rates!$A$5:$A$84,0)),"") -> nos | Q23: =IFERROR(INDEX(Rates!$D$5:$D$84,MATCH(M23,Rates!$A$5:$A$84,0)),0) -> 0.05 | R23: =O23*(1+Q23) -> 7191.2045 | S23: =IFERROR(INDEX(Rates!$E$5:$E$84,MATCH(M23,Rates!$A$5:$A$84,0)),0) -> 16 | T23: =R23*S23 -> 115059.27 | U23: =IF(M23="BRK",R23/2000,IF(OR(M23="SNDC",M23="SNDM",M23="CRS",M23="KHG",M23="EARTH"),R23/100,"")) -> 3.5956023
A24: S4 | B24: Foundations | C24: 4.5 | D24: Car-porch front corner | E24: PCC 1:4:8, 3", under isolated column footing | F24: 3'-6" x 3'-6" x 3" | G24: 3.5 x 3.5 x 0.25 | H24: 3.062 | I24: cft | J24: C5 | M24: CEM | N24: =IFERROR(INDEX(Rates!$B$5:$B$84,MATCH(M24,Rates!$A$5:$A$84,0)),"") -> Cement OPC, 50 kg bag (Lucky / Bestway / Maple Leaf) | O24: 0.2959 | P24: =IFERROR(INDEX(Rates!$C$5:$C$84,MATCH(M24,Rates!$A$5:$A$84,0)),"") -> bag | Q24: =IFERROR(INDEX(Rates!$D$5:$D$84,MATCH(M24,Rates!$A$5:$A$84,0)),0) -> 0.03 | R24: =O24*(1+Q24) -> 0.304777 | S24: =IFERROR(INDEX(Rates!$E$5:$E$84,MATCH(M24,Rates!$A$5:$A$84,0)),0) -> 1560 | T24: =R24*S24 -> 475.45212 | U24: =IF(M24="BRK",R24/2000,IF(OR(M24="SNDC",M24="SNDM",M24="CRS",M24="KHG",M24="EARTH"),R24/100,""))
A25: S4 | B25: Foundations | C25: 4.5 | J25: C5 | M25: SNDC | N25: =IFERROR(INDEX(Rates!$B$5:$B$84,MATCH(M25,Rates!$A$5:$A$84,0)),"") -> Chenab sand (concrete, screed) | O25: 1.4794 | P25: =IFERROR(INDEX(Rates!$C$5:$C$84,MATCH(M25,Rates!$A$5:$A$84,0)),"") -> cft | Q25: =IFERROR(INDEX(Rates!$D$5:$D$84,MATCH(M25,Rates!$A$5:$A$84,0)),0) -> 0.08 | R25: =O25*(1+Q25) -> 1.597752 | S25: =IFERROR(INDEX(Rates!$E$5:$E$84,MATCH(M25,Rates!$A$5:$A$84,0)),0) -> 65 | T25: =R25*S25 -> 103.85388 | U25: =IF(M25="BRK",R25/2000,IF(OR(M25="SNDC",M25="SNDM",M25="CRS",M25="KHG",M25="EARTH"),R25/100,"")) -> 0.01597752
A26: S4 | B26: Foundations | C26: 4.5 | J26: C5 | M26: CRS | N26: =IFERROR(INDEX(Rates!$B$5:$B$84,MATCH(M26,Rates!$A$5:$A$84,0)),"") -> Crush ¾" down, Sargodha (bajri) | O26: 2.9588 | P26: =IFERROR(INDEX(Rates!$C$5:$C$84,MATCH(M26,Rates!$A$5:$A$84,0)),"") -> cft | Q26: =IFERROR(INDEX(Rates!$D$5:$D$84,MATCH(M26,Rates!$A$5:$A$84,0)),0) -> 0.05 | R26: =O26*(1+Q26) -> 3.10674 | S26: =IFERROR(INDEX(Rates!$E$5:$E$84,MATCH(M26,Rates!$A$5:$A$84,0)),0) -> 110 | T26: =R26*S26 -> 341.7414 | U26: =IF(M26="BRK",R26/2000,IF(OR(M26="SNDC",M26="SNDM",M26="CRS",M26="KHG",M26="EARTH"),R26/100,"")) -> 0.0310674
A27: S4 | B27: Foundations | C27: 4.6 | D27: Car-porch front corner | E27: RCC isolated footing 1:2:4, 3'-0" x 3'-0" x 1'-0", #4 @ 6" both ways (the only RCC footing) | F27: 3' x 3' x 1' | G27: 9.0 cft; #4: 2 ways x 7 bars x 2'-9" | H27: 9 | I27: cft | J27: C5 | K27: Column footing | M27: CEM | N27: =IFERROR(INDEX(Rates!$B$5:$B$84,MATCH(M27,Rates!$A$5:$A$84,0)),"") -> Cement OPC, 50 kg bag (Lucky / Bestway / Maple Leaf) | O27: 1.6149 | P27: =IFERROR(INDEX(Rates!$C$5:$C$84,MATCH(M27,Rates!$A$5:$A$84,0)),"") -> bag | Q27: =IFERROR(INDEX(Rates!$D$5:$D$84,MATCH(M27,Rates!$A$5:$A$84,0)),0) -> 0.03 | R27: =O27*(1+Q27) -> 1.663347 | S27: =IFERROR(INDEX(Rates!$E$5:$E$84,MATCH(M27,Rates!$A$5:$A$84,0)),0) -> 1560 | T27: =R27*S27 -> 2594.8213 | U27: =IF(M27="BRK",R27/2000,IF(OR(M27="SNDC",M27="SNDM",M27="CRS",M27="KHG",M27="EARTH"),R27/100,""))
A28: S4 | B28: Foundations | C28: 4.6 | J28: C5 | K28: Column footing | M28: SNDC | N28: =IFERROR(INDEX(Rates!$B$5:$B$84,MATCH(M28,Rates!$A$5:$A$84,0)),"") -> Chenab sand (concrete, screed) | O28: 4.0371 | P28: =IFERROR(INDEX(Rates!$C$5:$C$84,MATCH(M28,Rates!$A$5:$A$84,0)),"") -> cft | Q28: =IFERROR(INDEX(Rates!$D$5:$D$84,MATCH(M28,Rates!$A$5:$A$84,0)),0) -> 0.08 | R28: =O28*(1+Q28) -> 4.360068 | S28: =IFERROR(INDEX(Rates!$E$5:$E$84,MATCH(M28,Rates!$A$5:$A$84,0)),0) -> 65 | T28: =R28*S28 -> 283.40442 | U28: =IF(M28="BRK",R28/2000,IF(OR(M28="SNDC",M28="SNDM",M28="CRS",M28="KHG",M28="EARTH"),R28/100,"")) -> 0.04360068
A29: S4 | B29: Foundations | C29: 4.6 | J29: C5 | K29: Column footing | M29: CRS | N29: =IFERROR(INDEX(Rates!$B$5:$B$84,MATCH(M29,Rates!$A$5:$A$84,0)),"") -> Crush ¾" down, Sargodha (bajri) | O29: 8.0743 | P29: =IFERROR(INDEX(Rates!$C$5:$C$84,MATCH(M29,Rates!$A$5:$A$84,0)),"") -> cft | Q29: =IFERROR(INDEX(Rates!$D$5:$D$84,MATCH(M29,Rates!$A$5:$A$84,0)),0) -> 0.05 | R29: =O29*(1+Q29) -> 8.478015 | S29: =IFERROR(INDEX(Rates!$E$5:$E$84,MATCH(M29,Rates!$A$5:$A$84,0)),0) -> 110 | T29: =R29*S29 -> 932.58165 | U29: =IF(M29="BRK",R29/2000,IF(OR(M29="SNDC",M29="SNDM",M29="CRS",M29="KHG",M29="EARTH"),R29/100,"")) -> 0.08478015
A30: S4 | B30: Foundations | C30: 4.6 | J30: C5 | K30: Column footing | M30: ST4 | N30: =IFERROR(INDEX(Rates!$B$5:$B$84,MATCH(M30,Rates!$A$5:$A$84,0)),"") -> Steel Grade 60 deformed, #4 (12 mm) | O30: 11.6655 | P30: =IFERROR(INDEX(Rates!$C$5:$C$84,MATCH(M30,Rates!$A$5:$A$84,0)),"") -> kg | Q30: =IFERROR(INDEX(Rates!$D$5:$D$84,MATCH(M30,Rates!$A$5:$A$84,0)),0) -> 0.04 | R30: =O30*(1+Q30) -> 12.13212 | S30: =IFERROR(INDEX(Rates!$E$5:$E$84,MATCH(M30,Rates!$A$5:$A$84,0)),0) -> 262 | T30: =R30*S30 -> 3178.6154 | U30: =IF(M30="BRK",R30/2000,IF(OR(M30="SNDC",M30="SNDM",M30="CRS",M30="KHG",M30="EARTH"),R30/100,""))
A31: S4 | B31: Foundations | C31: 4.7 | D31: Porch, lawn and gate edges | E31: Edge walls (D-D): PCC 1:4:8, 3" x 2'-6" | F31: 42.7 ft x 2'-6" x 3" | G31: 42.71 x 2.5 x 0.25 | H31: 26.694 | I31: cft | J31: C6, C3 | M31: CEM | N31: =IFERROR(INDEX(Rates!$B$5:$B$84,MATCH(M31,Rates!$A$5:$A$84,0)),"") -> Cement OPC, 50 kg bag (Lucky / Bestway / Maple Leaf) | O31: 2.579 | P31: =IFERROR(INDEX(Rates!$C$5:$C$84,MATCH(M31,Rates!$A$5:$A$84,0)),"") -> bag | Q31: =IFERROR(INDEX(Rates!$D$5:$D$84,MATCH(M31,Rates!$A$5:$A$84,0)),0) -> 0.03 | R31: =O31*(1+Q31) -> 2.65637 | S31: =IFERROR(INDEX(Rates!$E$5:$E$84,MATCH(M31,Rates!$A$5:$A$84,0)),0) -> 1560 | T31: =R31*S31 -> 4143.9372 | U31: =IF(M31="BRK",R31/2000,IF(OR(M31="SNDC",M31="SNDM",M31="CRS",M31="KHG",M31="EARTH"),R31/100,""))
A32: S4 | B32: Foundations | C32: 4.7 | J32: C6, C3 | M32: SNDC | N32: =IFERROR(INDEX(Rates!$B$5:$B$84,MATCH(M32,Rates!$A$5:$A$84,0)),"") -> Chenab sand (concrete, screed) | O32: 12.8951 | P32: =IFERROR(INDEX(Rates!$C$5:$C$84,MATCH(M32,Rates!$A$5:$A$84,0)),"") -> cft | Q32: =IFERROR(INDEX(Rates!$D$5:$D$84,MATCH(M32,Rates!$A$5:$A$84,0)),0) -> 0.08 | R32: =O32*(1+Q32) -> 13.926708 | S32: =IFERROR(INDEX(Rates!$E$5:$E$84,MATCH(M32,Rates!$A$5:$A$84,0)),0) -> 65 | T32: =R32*S32 -> 905.23602 | U32: =IF(M32="BRK",R32/2000,IF(OR(M32="SNDC",M32="SNDM",M32="CRS",M32="KHG",M32="EARTH"),R32/100,"")) -> 0.13926708
A33: S4 | B33: Foundations | C33: 4.7 | J33: C6, C3 | M33: CRS | N33: =IFERROR(INDEX(Rates!$B$5:$B$84,MATCH(M33,Rates!$A$5:$A$84,0)),"") -> Crush ¾" down, Sargodha (bajri) | O33: 25.7903 | P33: =IFERROR(INDEX(Rates!$C$5:$C$84,MATCH(M33,Rates!$A$5:$A$84,0)),"") -> cft | Q33: =IFERROR(INDEX(Rates!$D$5:$D$84,MATCH(M33,Rates!$A$5:$A$84,0)),0) -> 0.05 | R33: =O33*(1+Q33) -> 27.079815 | S33: =IFERROR(INDEX(Rates!$E$5:$E$84,MATCH(M33,Rates!$A$5:$A$84,0)),0) -> 110 | T33: =R33*S33 -> 2978.7796 | U33: =IF(M33="BRK",R33/2000,IF(OR(M33="SNDC",M33="SNDM",M33="CRS",M33="KHG",M33="EARTH"),R33/100,"")) -> 0.27079815
A34: S4 | B34: Foundations | C34: 4.8 | D34: Porch, lawn and gate edges | E34: Edge walls: brick steps 22½" / 18" / 13½" (6" each) in 1:6 | F34: 42.7 ft | G34: 42.71 x (1.875 + 1.5 + 1.125) x 0.5 | H34: 96.097 | I34: cft | J34: C6 | M34: CEM | N34: =IFERROR(INDEX(Rates!$B$5:$B$84,MATCH(M34,Rates!$A$5:$A$84,0)),"") -> Cement OPC, 50 kg bag (Lucky / Bestway / Maple Leaf) | O34: 4.382 | P34: =IFERROR(INDEX(Rates!$C$5:$C$84,MATCH(M34,Rates!$A$5:$A$84,0)),"") -> bag | Q34: =IFERROR(INDEX(Rates!$D$5:$D$84,MATCH(M34,Rates!$A$5:$A$84,0)),0) -> 0.03 | R34: =O34*(1+Q34) -> 4.51346 | S34: =IFERROR(INDEX(Rates!$E$5:$E$84,MATCH(M34,Rates!$A$5:$A$84,0)),0) -> 1560 | T34: =R34*S34 -> 7040.9976 | U34: =IF(M34="BRK",R34/2000,IF(OR(M34="SNDC",M34="SNDM",M34="CRS",M34="KHG",M34="EARTH"),R34/100,""))
A35: S4 | B35: Foundations | C35: 4.8 | J35: C6 | M35: SNDM | N35: =IFERROR(INDEX(Rates!$B$5:$B$84,MATCH(M35,Rates!$A$5:$A$84,0)),"") -> Ravi sand (mortar, plaster, blinding, fill) | O35: 32.8653 | P35: =IFERROR(INDEX(Rates!$C$5:$C$84,MATCH(M35,Rates!$A$5:$A$84,0)),"") -> cft | Q35: =IFERROR(INDEX(Rates!$D$5:$D$84,MATCH(M35,Rates!$A$5:$A$84,0)),0) -> 0.08 | R35: =O35*(1+Q35) -> 35.494524 | S35: =IFERROR(INDEX(Rates!$E$5:$E$84,MATCH(M35,Rates!$A$5:$A$84,0)),0) -> 40 | T35: =R35*S35 -> 1419.781 | U35: =IF(M35="BRK",R35/2000,IF(OR(M35="SNDC",M35="SNDM",M35="CRS",M35="KHG",M35="EARTH"),R35/100,"")) -> 0.35494524
A36: S4 | B36: Foundations | C36: 4.8 | J36: C6 | M36: BRK | N36: =IFERROR(INDEX(Rates!$B$5:$B$84,MATCH(M36,Rates!$A$5:$A$84,0)),"") -> Bricks, first class (awwal), 9" x 4½" x 3" | O36: 1297.3162 | P36: =IFERROR(INDEX(Rates!$C$5:$C$84,MATCH(M36,Rates!$A$5:$A$84,0)),"") -> nos | Q36: =IFERROR(INDEX(Rates!$D$5:$D$84,MATCH(M36,Rates!$A$5:$A$84,0)),0) -> 0.05 | R36: =O36*(1+Q36) -> 1362.182 | S36: =IFERROR(INDEX(Rates!$E$5:$E$84,MATCH(M36,Rates!$A$5:$A$84,0)),0) -> 16 | T36: =R36*S36 -> 21794.912 | U36: =IF(M36="BRK",R36/2000,IF(OR(M36="SNDC",M36="SNDM",M36="CRS",M36="KHG",M36="EARTH"),R36/100,"")) -> 0.681091
A37: S4 | B37: Foundations | C37: 4.9 | D37: Porch, lawn and gate edges | E37: Edge walls: 9" wall in 1:6 from step top (-2'-0") to +1'-1½" (under DPC) | F37: 42.7 ft x 9" x 3'-1½" | G37: 42.71 x 0.75 x 3.125 | H37: 100.102 | I37: cft | J37: C6, D1 | M37: CEM | N37: =IFERROR(INDEX(Rates!$B$5:$B$84,MATCH(M37,Rates!$A$5:$A$84,0)),"") -> Cement OPC, 50 kg bag (Lucky / Bestway / Maple Leaf) | O37: 4.5646 | P37: =IFERROR(INDEX(Rates!$C$5:$C$84,MATCH(M37,Rates!$A$5:$A$84,0)),"") -> bag | Q37: =IFERROR(INDEX(Rates!$D$5:$D$84,MATCH(M37,Rates!$A$5:$A$84,0)),0) -> 0.03 | R37: =O37*(1+Q37) -> 4.701538 | S37: =IFERROR(INDEX(Rates!$E$5:$E$84,MATCH(M37,Rates!$A$5:$A$84,0)),0) -> 1560 | T37: =R37*S37 -> 7334.3993 | U37: =IF(M37="BRK",R37/2000,IF(OR(M37="SNDC",M37="SNDM",M37="CRS",M37="KHG",M37="EARTH"),R37/100,""))
A38: S4 | B38: Foundations | C38: 4.9 | J38: C6, D1 | M38: SNDM | N38: =IFERROR(INDEX(Rates!$B$5:$B$84,MATCH(M38,Rates!$A$5:$A$84,0)),"") -> Ravi sand (mortar, plaster, blinding, fill) | O38: 34.2347 | P38: =IFERROR(INDEX(Rates!$C$5:$C$84,MATCH(M38,Rates!$A$5:$A$84,0)),"") -> cft | Q38: =IFERROR(INDEX(Rates!$D$5:$D$84,MATCH(M38,Rates!$A$5:$A$84,0)),0) -> 0.08 | R38: =O38*(1+Q38) -> 36.973476 | S38: =IFERROR(INDEX(Rates!$E$5:$E$84,MATCH(M38,Rates!$A$5:$A$84,0)),0) -> 40 | T38: =R38*S38 -> 1478.939 | U38: =IF(M38="BRK",R38/2000,IF(OR(M38="SNDC",M38="SNDM",M38="CRS",M38="KHG",M38="EARTH"),R38/100,"")) -> 0.36973476
A39: S4 | B39: Foundations | C39: 4.9 | J39: C6, D1 | M39: BRK | N39: =IFERROR(INDEX(Rates!$B$5:$B$84,MATCH(M39,Rates!$A$5:$A$84,0)),"") -> Bricks, first class (awwal), 9" x 4½" x 3" | O39: 1351.3711 | P39: =IFERROR(INDEX(Rates!$C$5:$C$84,MATCH(M39,Rates!$A$5:$A$84,0)),"") -> nos | Q39: =IFERROR(INDEX(Rates!$D$5:$D$84,MATCH(M39,Rates!$A$5:$A$84,0)),0) -> 0.05 | R39: =O39*(1+Q39) -> 1418.9397 | S39: =IFERROR(INDEX(Rates!$E$5:$E$84,MATCH(M39,Rates!$A$5:$A$84,0)),0) -> 16 | T39: =R39*S39 -> 22703.034 | U39: =IF(M39="BRK",R39/2000,IF(OR(M39="SNDC",M39="SNDM",M39="CRS",M39="KHG",M39="EARTH"),R39/100,"")) -> 0.70946983
A40: S4 | B40: Foundations | C40: 4.10 | D40: Porch, lawn and gate edges | E40: Edge walls: DPC 1½" 1:2:4 with waterproofing compound + 2 coats hot bitumen, top at porch level | F40: 42.7 ft x 9" | G40: 42.71 x 0.75 x 0.125; bitumen 32.0 sft x 0.4 kg | H40: 4.004 | I40: cft | J40: B4, C6 | M40: CEM | N40: =IFERROR(INDEX(Rates!$B$5:$B$84,MATCH(M40,Rates!$A$5:$A$84,0)),"") -> Cement OPC, 50 kg bag (Lucky / Bestway / Maple Leaf) | O40: 0.7184 | P40: =IFERROR(INDEX(Rates!$C$5:$C$84,MATCH(M40,Rates!$A$5:$A$84,0)),"") -> bag | Q40: =IFERROR(INDEX(Rates!$D$5:$D$84,MATCH(M40,Rates!$A$5:$A$84,0)),0) -> 0.03 | R40: =O40*(1+Q40) -> 0.739952 | S40: =IFERROR(INDEX(Rates!$E$5:$E$84,MATCH(M40,Rates!$A$5:$A$84,0)),0) -> 1560 | T40: =R40*S40 -> 1154.3251 | U40: =IF(M40="BRK",R40/2000,IF(OR(M40="SNDC",M40="SNDM",M40="CRS",M40="KHG",M40="EARTH"),R40/100,""))
A41: S4 | B41: Foundations | C41: 4.10 | J41: B4, C6 | M41: SNDC | N41: =IFERROR(INDEX(Rates!$B$5:$B$84,MATCH(M41,Rates!$A$5:$A$84,0)),"") -> Chenab sand (concrete, screed) | O41: 1.7961 | P41: =IFERROR(INDEX(Rates!$C$5:$C$84,MATCH(M41,Rates!$A$5:$A$84,0)),"") -> cft | Q41: =IFERROR(INDEX(Rates!$D$5:$D$84,MATCH(M41,Rates!$A$5:$A$84,0)),0) -> 0.08 | R41: =O41*(1+Q41) -> 1.939788 | S41: =IFERROR(INDEX(Rates!$E$5:$E$84,MATCH(M41,Rates!$A$5:$A$84,0)),0) -> 65 | T41: =R41*S41 -> 126.08622 | U41: =IF(M41="BRK",R41/2000,IF(OR(M41="SNDC",M41="SNDM",M41="CRS",M41="KHG",M41="EARTH"),R41/100,"")) -> 0.01939788
...

Sheet Totals
A1: Totals by material - purchase quantities rounded to buying units
A2: Net = SUMIF of BOQ; Gross = Net x (1 + wastage); Purchase = Gross rounded UP to the buying unit; Cost = Purchase x Rate.
A4: Key | B4: Material | C4: Unit | D4: Net qty | E4: Wastage % | F4: Gross qty | G4: Buying unit | H4: Unit size | I4: Purchase qty | J4: No. of buying units | K4: Rate (PKR) | L4: Cost (PKR) | M4: Tractor-trolley loads | N4: Group
A5: CEM | B5: =INDEX(Rates!$B$5:$B$84,MATCH(A5,Rates!$A$5:$A$84,0)) -> Cement OPC, 50 kg bag (Lucky / Bestway / Maple Leaf) | C5: =INDEX(Rates!$C$5:$C$84,MATCH(A5,Rates!$A$5:$A$84,0)) -> bag | D5: =SUMIF(BOQ!$M$5:$M$452,A5,BOQ!$O$5:$O$452) -> 1498.8854 | E5: =IFERROR(INDEX(Rates!$D$5:$D$84,MATCH(A5,Rates!$A$5:$A$84,0)),0) -> 0.03 | F5: =D5*(1+E5) -> 1543.852 | G5: =INDEX(Rates!$F$5:$F$84,MATCH(A5,Rates!$A$5:$A$84,0)) -> bag | H5: =INDEX(Rates!$G$5:$G$84,MATCH(A5,Rates!$A$5:$A$84,0)) -> 1 | I5: =ROUNDUP(F5/H5,0)*H5 -> 1544 | J5: =I5/H5 -> 1544 | K5: =IFERROR(INDEX(Rates!$E$5:$E$84,MATCH(A5,Rates!$A$5:$A$84,0)),0) -> 1560 | L5: =I5*K5 -> 2408640 | M5: =IF(A5="BRK",ROUNDUP(I5/2000,0),IF(OR(A5="SNDC",A5="SNDM",A5="CRS",A5="KHG",A5="EARTH"),ROUNDUP(I5/100,0),"")) | N5: =INDEX(Rates!$J$5:$J$84,MATCH(A5,Rates!$A$5:$A$84,0)) -> Cement
A6: BRK | B6: =INDEX(Rates!$B$5:$B$84,MATCH(A6,Rates!$A$5:$A$84,0)) -> Bricks, first class (awwal), 9" x 4½" x 3" | C6: =INDEX(Rates!$C$5:$C$84,MATCH(A6,Rates!$A$5:$A$84,0)) -> nos | D6: =SUMIF(BOQ!$M$5:$M$452,A6,BOQ!$O$5:$O$452) -> 126535.51 | E6: =IFERROR(INDEX(Rates!$D$5:$D$84,MATCH(A6,Rates!$A$5:$A$84,0)),0) -> 0.05 | F6: =D6*(1+E6) -> 132862.28 | G6: =INDEX(Rates!$F$5:$F$84,MATCH(A6,Rates!$A$5:$A$84,0)) -> 1,000 bricks | H6: =INDEX(Rates!$G$5:$G$84,MATCH(A6,Rates!$A$5:$A$84,0)) -> 1000 | I6: =ROUNDUP(F6/H6,0)*H6 -> 133000 | J6: =I6/H6 -> 133 | K6: =IFERROR(INDEX(Rates!$E$5:$E$84,MATCH(A6,Rates!$A$5:$A$84,0)),0) -> 16 | L6: =I6*K6 -> 2128000 | M6: =IF(A6="BRK",ROUNDUP(I6/2000,0),IF(OR(A6="SNDC",A6="SNDM",A6="CRS",A6="KHG",A6="EARTH"),ROUNDUP(I6/100,0),"")) -> 67 | N6: =INDEX(Rates!$J$5:$J$84,MATCH(A6,Rates!$A$5:$A$84,0)) -> Bricks
A7: ST2 | B7: =INDEX(Rates!$B$5:$B$84,MATCH(A7,Rates!$A$5:$A$84,0)) -> Steel Grade 60 deformed, #2 (6 mm) rings | C7: =INDEX(Rates!$C$5:$C$84,MATCH(A7,Rates!$A$5:$A$84,0)) -> kg | D7: =SUMIF(BOQ!$M$5:$M$452,A7,BOQ!$O$5:$O$452) -> 155.1304 | E7: =IFERROR(INDEX(Rates!$D$5:$D$84,MATCH(A7,Rates!$A$5:$A$84,0)),0) -> 0.04 | F7: =D7*(1+E7) -> 161.33562 | G7: =INDEX(Rates!$F$5:$F$84,MATCH(A7,Rates!$A$5:$A$84,0)) -> 10 kg | H7: =INDEX(Rates!$G$5:$G$84,MATCH(A7,Rates!$A$5:$A$84,0)) -> 10 | I7: =ROUNDUP(F7/H7,0)*H7 -> 170 | J7: =I7/H7 -> 17 | K7: =IFERROR(INDEX(Rates!$E$5:$E$84,MATCH(A7,Rates!$A$5:$A$84,0)),0) -> 270 | L7: =I7*K7 -> 45900 | M7: =IF(A7="BRK",ROUNDUP(I7/2000,0),IF(OR(A7="SNDC",A7="SNDM",A7="CRS",A7="KHG",A7="EARTH"),ROUNDUP(I7/100,0),"")) | N7: =INDEX(Rates!$J$5:$J$84,MATCH(A7,Rates!$A$5:$A$84,0)) -> Steel
A8: ST3 | B8: =INDEX(Rates!$B$5:$B$84,MATCH(A8,Rates!$A$5:$A$84,0)) -> Steel Grade 60 deformed, #3 (10 mm) (Amreli / Mughal / FF Steel) | C8: =INDEX(Rates!$C$5:$C$84,MATCH(A8,Rates!$A$5:$A$84,0)) -> kg | D8: =SUMIF(BOQ!$M$5:$M$452,A8,BOQ!$O$5:$O$452) -> 3785.6276 | E8: =IFERROR(INDEX(Rates!$D$5:$D$84,MATCH(A8,Rates!$A$5:$A$84,0)),0) -> 0.04 | F8: =D8*(1+E8) -> 3937.0527 | G8: =INDEX(Rates!$F$5:$F$84,MATCH(A8,Rates!$A$5:$A$84,0)) -> 10 kg | H8: =INDEX(Rates!$G$5:$G$84,MATCH(A8,Rates!$A$5:$A$84,0)) -> 10 | I8: =ROUNDUP(F8/H8,0)*H8 -> 3940 | J8: =I8/H8 -> 394 | K8: =IFERROR(INDEX(Rates!$E$5:$E$84,MATCH(A8,Rates!$A$5:$A$84,0)),0) -> 262 | L8: =I8*K8 -> 1032280 | M8: =IF(A8="BRK",ROUNDUP(I8/2000,0),IF(OR(A8="SNDC",A8="SNDM",A8="CRS",A8="KHG",A8="EARTH"),ROUNDUP(I8/100,0),"")) | N8: =INDEX(Rates!$J$5:$J$84,MATCH(A8,Rates!$A$5:$A$84,0)) -> Steel
A9: ST4 | B9: =INDEX(Rates!$B$5:$B$84,MATCH(A9,Rates!$A$5:$A$84,0)) -> Steel Grade 60 deformed, #4 (12 mm) | C9: =INDEX(Rates!$C$5:$C$84,MATCH(A9,Rates!$A$5:$A$84,0)) -> kg | D9: =SUMIF(BOQ!$M$5:$M$452,A9,BOQ!$O$5:$O$452) -> 2165.0331 | E9: =IFERROR(INDEX(Rates!$D$5:$D$84,MATCH(A9,Rates!$A$5:$A$84,0)),0) -> 0.04 | F9: =D9*(1+E9) -> 2251.6344 | G9: =INDEX(Rates!$F$5:$F$84,MATCH(A9,Rates!$A$5:$A$84,0)) -> 10 kg | H9: =INDEX(Rates!$G$5:$G$84,MATCH(A9,Rates!$A$5:$A$84,0)) -> 10 | I9: =ROUNDUP(F9/H9,0)*H9 -> 2260 | J9: =I9/H9 -> 226 | K9: =IFERROR(INDEX(Rates!$E$5:$E$84,MATCH(A9,Rates!$A$5:$A$84,0)),0) -> 262 | L9: =I9*K9 -> 592120 | M9: =IF(A9="BRK",ROUNDUP(I9/2000,0),IF(OR(A9="SNDC",A9="SNDM",A9="CRS",A9="KHG",A9="EARTH"),ROUNDUP(I9/100,0),"")) | N9: =INDEX(Rates!$J$5:$J$84,MATCH(A9,Rates!$A$5:$A$84,0)) -> Steel
A10: ST6 | B10: =INDEX(Rates!$B$5:$B$84,MATCH(A10,Rates!$A$5:$A$84,0)) -> Steel Grade 60 deformed, #6 (20 mm) | C10: =INDEX(Rates!$C$5:$C$84,MATCH(A10,Rates!$A$5:$A$84,0)) -> kg | D10: =SUMIF(BOQ!$M$5:$M$452,A10,BOQ!$O$5:$O$452) -> 974.5926 | E10: =IFERROR(INDEX(Rates!$D$5:$D$84,MATCH(A10,Rates!$A$5:$A$84,0)),0) -> 0.04 | F10: =D10*(1+E10) -> 1013.5763 | G10: =INDEX(Rates!$F$5:$F$84,MATCH(A10,Rates!$A$5:$A$84,0)) -> 10 kg | H10: =INDEX(Rates!$G$5:$G$84,MATCH(A10,Rates!$A$5:$A$84,0)) -> 10 | I10: =ROUNDUP(F10/H10,0)*H10 -> 1020 | J10: =I10/H10 -> 102 | K10: =IFERROR(INDEX(Rates!$E$5:$E$84,MATCH(A10,Rates!$A$5:$A$84,0)),0) -> 262 | L10: =I10*K10 -> 267240 | M10: =IF(A10="BRK",ROUNDUP(I10/2000,0),IF(OR(A10="SNDC",A10="SNDM",A10="CRS",A10="KHG",A10="EARTH"),ROUNDUP(I10/100,0),"")) | N10: =INDEX(Rates!$J$5:$J$84,MATCH(A10,Rates!$A$5:$A$84,0)) -> Steel
A11: BWIRE | B11: =INDEX(Rates!$B$5:$B$84,MATCH(A11,Rates!$A$5:$A$84,0)) -> Binding wire, annealed 18 gauge | C11: =INDEX(Rates!$C$5:$C$84,MATCH(A11,Rates!$A$5:$A$84,0)) -> kg | D11: =(F7+F8+F9+F10)*0.01 -> 73.63599 | E11: =IFERROR(INDEX(Rates!$D$5:$D$84,MATCH(A11,Rates!$A$5:$A$84,0)),0) -> 0 | F11: =D11*(1+E11) -> 73.63599 | G11: =INDEX(Rates!$F$5:$F$84,MATCH(A11,Rates!$A$5:$A$84,0)) -> 5 kg | H11: =INDEX(Rates!$G$5:$G$84,MATCH(A11,Rates!$A$5:$A$84,0)) -> 5 | I11: =ROUNDUP(F11/H11,0)*H11 -> 75 | J11: =I11/H11 -> 15 | K11: =IFERROR(INDEX(Rates!$E$5:$E$84,MATCH(A11,Rates!$A$5:$A$84,0)),0) -> 400 | L11: =I11*K11 -> 30000 | M11: =IF(A11="BRK",ROUNDUP(I11/2000,0),IF(OR(A11="SNDC",A11="SNDM",A11="CRS",A11="KHG",A11="EARTH"),ROUNDUP(I11/100,0),"")) | N11: =INDEX(Rates!$J$5:$J$84,MATCH(A11,Rates!$A$5:$A$84,0)) -> Steel
A12: SNDC | B12: =INDEX(Rates!$B$5:$B$84,MATCH(A12,Rates!$A$5:$A$84,0)) -> Chenab sand (concrete, screed) | C12: =INDEX(Rates!$C$5:$C$84,MATCH(A12,Rates!$A$5:$A$84,0)) -> cft | D12: =SUMIF(BOQ!$M$5:$M$452,A12,BOQ!$O$5:$O$452) -> 2332.4668 | E12: =IFERROR(INDEX(Rates!$D$5:$D$84,MATCH(A12,Rates!$A$5:$A$84,0)),0) -> 0.08 | F12: =D12*(1+E12) -> 2519.0641 | G12: =INDEX(Rates!$F$5:$F$84,MATCH(A12,Rates!$A$5:$A$84,0)) -> 50 cft | H12: =INDEX(Rates!$G$5:$G$84,MATCH(A12,Rates!$A$5:$A$84,0)) -> 50 | I12: =ROUNDUP(F12/H12,0)*H12 -> 2550 | J12: =I12/H12 -> 51 | K12: =IFERROR(INDEX(Rates!$E$5:$E$84,MATCH(A12,Rates!$A$5:$A$84,0)),0) -> 65 | L12: =I12*K12 -> 165750 | M12: =IF(A12="BRK",ROUNDUP(I12/2000,0),IF(OR(A12="SNDC",A12="SNDM",A12="CRS",A12="KHG",A12="EARTH"),ROUNDUP(I12/100,0),"")) -> 26 | N12: =INDEX(Rates!$J$5:$J$84,MATCH(A12,Rates!$A$5:$A$84,0)) -> Sand
A13: SNDM | B13: =INDEX(Rates!$B$5:$B$84,MATCH(A13,Rates!$A$5:$A$84,0)) -> Ravi sand (mortar, plaster, blinding, fill) | C13: =INDEX(Rates!$C$5:$C$84,MATCH(A13,Rates!$A$5:$A$84,0)) -> cft | D13: =SUMIF(BOQ!$M$5:$M$452,A13,BOQ!$O$5:$O$452) -> 4960.4088 | E13: =IFERROR(INDEX(Rates!$D$5:$D$84,MATCH(A13,Rates!$A$5:$A$84,0)),0) -> 0.08 | F13: =D13*(1+E13) -> 5357.2415 | G13: =INDEX(Rates!$F$5:$F$84,MATCH(A13,Rates!$A$5:$A$84,0)) -> 50 cft | H13: =INDEX(Rates!$G$5:$G$84,MATCH(A13,Rates!$A$5:$A$84,0)) -> 50 | I13: =ROUNDUP(F13/H13,0)*H13 -> 5400 | J13: =I13/H13 -> 108 | K13: =IFERROR(INDEX(Rates!$E$5:$E$84,MATCH(A13,Rates!$A$5:$A$84,0)),0) -> 40 | L13: =I13*K13 -> 216000 | M13: =IF(A13="BRK",ROUNDUP(I13/2000,0),IF(OR(A13="SNDC",A13="SNDM",A13="CRS",A13="KHG",A13="EARTH"),ROUNDUP(I13/100,0),"")) -> 54 | N13: =INDEX(Rates!$J$5:$J$84,MATCH(A13,Rates!$A$5:$A$84,0)) -> Sand
A14: CRS | B14: =INDEX(Rates!$B$5:$B$84,MATCH(A14,Rates!$A$5:$A$84,0)) -> Crush ¾" down, Sargodha (bajri) | C14: =INDEX(Rates!$C$5:$C$84,MATCH(A14,Rates!$A$5:$A$84,0)) -> cft | D14: =SUMIF(BOQ!$M$5:$M$452,A14,BOQ!$O$5:$O$452) -> 3801.3592 | E14: =IFERROR(INDEX(Rates!$D$5:$D$84,MATCH(A14,Rates!$A$5:$A$84,0)),0) -> 0.05 | F14: =D14*(1+E14) -> 3991.4272 | G14: =INDEX(Rates!$F$5:$F$84,MATCH(A14,Rates!$A$5:$A$84,0)) -> 50 cft | H14: =INDEX(Rates!$G$5:$G$84,MATCH(A14,Rates!$A$5:$A$84,0)) -> 50 | I14: =ROUNDUP(F14/H14,0)*H14 -> 4000 | J14: =I14/H14 -> 80 | K14: =IFERROR(INDEX(Rates!$E$5:$E$84,MATCH(A14,Rates!$A$5:$A$84,0)),0) -> 110 | L14: =I14*K14 -> 440000 | M14: =IF(A14="BRK",ROUNDUP(I14/2000,0),IF(OR(A14="SNDC",A14="SNDM",A14="CRS",A14="KHG",A14="EARTH"),ROUNDUP(I14/100,0),"")) -> 40 | N14: =INDEX(Rates!$J$5:$J$84,MATCH(A14,Rates!$A$5:$A$84,0)) -> Crush
A15: KHG | B15: =INDEX(Rates!$B$5:$B$84,MATCH(A15,Rates!$A$5:$A$84,0)) -> Stone ballast (khangar) 1½"-2½" | C15: =INDEX(Rates!$C$5:$C$84,MATCH(A15,Rates!$A$5:$A$84,0)) -> cft | D15: =SUMIF(BOQ!$M$5:$M$452,A15,BOQ!$O$5:$O$452) -> 665.0558 | E15: =IFERROR(INDEX(Rates!$D$5:$D$84,MATCH(A15,Rates!$A$5:$A$84,0)),0) -> 0.05 | F15: =D15*(1+E15) -> 698.30859 | G15: =INDEX(Rates!$F$5:$F$84,MATCH(A15,Rates!$A$5:$A$84,0)) -> 50 cft | H15: =INDEX(Rates!$G$5:$G$84,MATCH(A15,Rates!$A$5:$A$84,0)) -> 50 | I15: =ROUNDUP(F15/H15,0)*H15 -> 700 | J15: =I15/H15 -> 14 | K15: =IFERROR(INDEX(Rates!$E$5:$E$84,MATCH(A15,Rates!$A$5:$A$84,0)),0) -> 90 | L15: =I15*K15 -> 63000 | M15: =IF(A15="BRK",ROUNDUP(I15/2000,0),IF(OR(A15="SNDC",A15="SNDM",A15="CRS",A15="KHG",A15="EARTH"),ROUNDUP(I15/100,0),"")) -> 7 | N15: =INDEX(Rates!$J$5:$J$84,MATCH(A15,Rates!$A$5:$A$84,0)) -> Stone ballast
A16: EARTH | B16: =INDEX(Rates!$B$5:$B$84,MATCH(A16,Rates!$A$5:$A$84,0)) -> Earth (mitti) for filling, delivered | C16: =INDEX(Rates!$C$5:$C$84,MATCH(A16,Rates!$A$5:$A$84,0)) -> cft | D16: =SUMIF(BOQ!$M$5:$M$452,A16,BOQ!$O$5:$O$452) -> 4184.7993 | E16: =IFERROR(INDEX(Rates!$D$5:$D$84,MATCH(A16,Rates!$A$5:$A$84,0)),0) -> 0 | F16: =D16*(1+E16) -> 4184.7993 | G16: =INDEX(Rates!$F$5:$F$84,MATCH(A16,Rates!$A$5:$A$84,0)) -> 50 cft | H16: =INDEX(Rates!$G$5:$G$84,MATCH(A16,Rates!$A$5:$A$84,0)) -> 50 | I16: =ROUNDUP(F16/H16,0)*H16 -> 4200 | J16: =I16/H16 -> 84 | K16: =IFERROR(INDEX(Rates!$E$5:$E$84,MATCH(A16,Rates!$A$5:$A$84,0)),0) -> 25 | L16: =I16*K16 -> 105000 | M16: =IF(A16="BRK",ROUNDUP(I16/2000,0),IF(OR(A16="SNDC",A16="SNDM",A16="CRS",A16="KHG",A16="EARTH"),ROUNDUP(I16/100,0),"")) -> 42 | N16: =INDEX(Rates!$J$5:$J$84,MATCH(A16,Rates!$A$5:$A$84,0)) -> Earth
A17: POLY | B17: =INDEX(Rates!$B$5:$B$84,MATCH(A17,Rates!$A$5:$A$84,0)) -> Polythene sheet 0.2 mm (800 gauge) | C17: =INDEX(Rates!$C$5:$C$84,MATCH(A17,Rates!$A$5:$A$84,0)) -> kg | D17: =SUMIF(BOQ!$M$5:$M$452,A17,BOQ!$O$5:$O$452) -> 37.3677 | E17: =IFERROR(INDEX(Rates!$D$5:$D$84,MATCH(A17,Rates!$A$5:$A$84,0)),0) -> 0.05 | F17: =D17*(1+E17) -> 39.236085 | G17: =INDEX(Rates!$F$5:$F$84,MATCH(A17,Rates!$A$5:$A$84,0)) -> kg | H17: =INDEX(Rates!$G$5:$G$84,MATCH(A17,Rates!$A$5:$A$84,0)) -> 1 | I17: =ROUNDUP(F17/H17,0)*H17 -> 40 | J17: =I17/H17 -> 40 | K17: =IFERROR(INDEX(Rates!$E$5:$E$84,MATCH(A17,Rates!$A$5:$A$84,0)),0) -> 550 | L17: =I17*K17 -> 22000 | M17: =IF(A17="BRK",ROUNDUP(I17/2000,0),IF(OR(A17="SNDC",A17="SNDM",A17="CRS",A17="KHG",A17="EARTH"),ROUNDUP(I17/100,0),"")) | N17: =INDEX(Rates!$J$5:$J$84,MATCH(A17,Rates!$A$5:$A$84,0)) -> Waterproofing
A18: BIT | B18: =INDEX(Rates!$B$5:$B$84,MATCH(A18,Rates!$A$5:$A$84,0)) -> Hot bitumen 60/70 (drum) | C18: =INDEX(Rates!$C$5:$C$84,MATCH(A18,Rates!$A$5:$A$84,0)) -> kg | D18: =SUMIF(BOQ!$M$5:$M$452,A18,BOQ!$O$5:$O$452) -> 472.3428 | E18: =IFERROR(INDEX(Rates!$D$5:$D$84,MATCH(A18,Rates!$A$5:$A$84,0)),0) -> 0.05 | F18: =D18*(1+E18) -> 495.95994 | G18: =INDEX(Rates!$F$5:$F$84,MATCH(A18,Rates!$A$5:$A$84,0)) -> 10 kg | H18: =INDEX(Rates!$G$5:$G$84,MATCH(A18,Rates!$A$5:$A$84,0)) -> 10 | I18: =ROUNDUP(F18/H18,0)*H18 -> 500 | J18: =I18/H18 -> 50 | K18: =IFERROR(INDEX(Rates!$E$5:$E$84,MATCH(A18,Rates!$A$5:$A$84,0)),0) -> 280 | L18: =I18*K18 -> 140000 | M18: =IF(A18="BRK",ROUNDUP(I18/2000,0),IF(OR(A18="SNDC",A18="SNDM",A18="CRS",A18="KHG",A18="EARTH"),ROUNDUP(I18/100,0),"")) | N18: =INDEX(Rates!$J$5:$J$84,MATCH(A18,Rates!$A$5:$A$84,0)) -> Waterproofing
A19: ADMX | B19: =INDEX(Rates!$B$5:$B$84,MATCH(A19,Rates!$A$5:$A$84,0)) -> Integral waterproofing compound (powder), 1 kg per bag of cement | C19: =INDEX(Rates!$C$5:$C$84,MATCH(A19,Rates!$A$5:$A$84,0)) -> kg | D19: =SUMIF(BOQ!$M$5:$M$452,A19,BOQ!$O$5:$O$452) -> 47.0705 | E19: =IFERROR(INDEX(Rates!$D$5:$D$84,MATCH(A19,Rates!$A$5:$A$84,0)),0) -> 0 | F19: =D19*(1+E19) -> 47.0705 | G19: =INDEX(Rates!$F$5:$F$84,MATCH(A19,Rates!$A$5:$A$84,0)) -> kg | H19: =INDEX(Rates!$G$5:$G$84,MATCH(A19,Rates!$A$5:$A$84,0)) -> 1 | I19: =ROUNDUP(F19/H19,0)*H19 -> 48 | J19: =I19/H19 -> 48 | K19: =IFERROR(INDEX(Rates!$E$5:$E$84,MATCH(A19,Rates!$A$5:$A$84,0)),0) -> 350 | L19: =I19*K19 -> 16800 | M19: =IF(A19="BRK",ROUNDUP(I19/2000,0),IF(OR(A19="SNDC",A19="SNDM",A19="CRS",A19="KHG",A19="EARTH"),ROUNDUP(I19/100,0),"")) | N19: =INDEX(Rates!$J$5:$J$84,MATCH(A19,Rates!$A$5:$A$84,0)) -> Waterproofing
A20: PRIM | B20: =INDEX(Rates!$B$5:$B$84,MATCH(A20,Rates!$A$5:$A$84,0)) -> Bitumen primer | C20: =INDEX(Rates!$C$5:$C$84,MATCH(A20,Rates!$A$5:$A$84,0)) -> L | D20: =SUMIF(BOQ!$M$5:$M$452,A20,BOQ!$O$5:$O$452) -> 62.8872 | E20: =IFERROR(INDEX(Rates!$D$5:$D$84,MATCH(A20,Rates!$A$5:$A$84,0)),0) -> 0.05 | F20: =D20*(1+E20) -> 66.03156 | G20: =INDEX(Rates!$F$5:$F$84,MATCH(A20,Rates!$A$5:$A$84,0)) -> 4 L tin | H20: =INDEX(Rates!$G$5:$G$84,MATCH(A20,Rates!$A$5:$A$84,0)) -> 4 | I20: =ROUNDUP(F20/H20,0)*H20 -> 68 | J20: =I20/H20 -> 17 | K20: =IFERROR(INDEX(Rates!$E$5:$E$84,MATCH(A20,Rates!$A$5:$A$84,0)),0) -> 900 | L20: =I20*K20 -> 61200 | M20: =IF(A20="BRK",ROUNDUP(I20/2000,0),IF(OR(A20="SNDC",A20="SNDM",A20="CRS",A20="KHG",A20="EARTH"),ROUNDUP(I20/100,0),"")) | N20: =INDEX(Rates!$J$5:$J$84,MATCH(A20,Rates!$A$5:$A$84,0)) -> Waterproofing
A21: MEMB | B21: =INDEX(Rates!$B$5:$B$84,MATCH(A21,Rates!$A$5:$A$84,0)) -> 4 mm APP/SBS modified-bitumen membrane (1 m x 10 m roll) | C21: =INDEX(Rates!$C$5:$C$84,MATCH(A21,Rates!$A$5:$A$84,0)) -> m2 | D21: =SUMIF(BOQ!$M$5:$M$452,A21,BOQ!$O$5:$O$452) -> 209.6239 | E21: =IFERROR(INDEX(Rates!$D$5:$D$84,MATCH(A21,Rates!$A$5:$A$84,0)),0) -> 0.05 | F21: =D21*(1+E21) -> 220.1051 | G21: =INDEX(Rates!$F$5:$F$84,MATCH(A21,Rates!$A$5:$A$84,0)) -> roll (10 m2) | H21: =INDEX(Rates!$G$5:$G$84,MATCH(A21,Rates!$A$5:$A$84,0)) -> 10 | I21: =ROUNDUP(F21/H21,0)*H21 -> 230 | J21: =I21/H21 -> 23 | K21: =IFERROR(INDEX(Rates!$E$5:$E$84,MATCH(A21,Rates!$A$5:$A$84,0)),0) -> 700 | L21: =I21*K21 -> 161000 | M21: =IF(A21="BRK",ROUNDUP(I21/2000,0),IF(OR(A21="SNDC",A21="SNDM",A21="CRS",A21="KHG",A21="EARTH"),ROUNDUP(I21/100,0),"")) | N21: =INDEX(Rates!$J$5:$J$84,MATCH(A21,Rates!$A$5:$A$84,0)) -> Waterproofing
A22: LPG | B22: =INDEX(Rates!$B$5:$B$84,MATCH(A22,Rates!$A$5:$A$84,0)) -> LPG for torching (11.8 kg cylinder) | C22: =INDEX(Rates!$C$5:$C$84,MATCH(A22,Rates!$A$5:$A$84,0)) -> kg | D22: =SUMIF(BOQ!$M$5:$M$452,A22,BOQ!$O$5:$O$452) -> 83.8496 | E22: =IFERROR(INDEX(Rates!$D$5:$D$84,MATCH(A22,Rates!$A$5:$A$84,0)),0) -> 0 | F22: =D22*(1+E22) -> 83.8496 | G22: =INDEX(Rates!$F$5:$F$84,MATCH(A22,Rates!$A$5:$A$84,0)) -> cylinder (11.8 kg) | H22: =INDEX(Rates!$G$5:$G$84,MATCH(A22,Rates!$A$5:$A$84,0)) -> 11.8 | I22: =ROUNDUP(F22/H22,0)*H22 -> 94.4 | J22: =I22/H22 -> 8 | K22: =IFERROR(INDEX(Rates!$E$5:$E$84,MATCH(A22,Rates!$A$5:$A$84,0)),0) -> 300 | L22: =I22*K22 -> 28320 | M22: =IF(A22="BRK",ROUNDUP(I22/2000,0),IF(OR(A22="SNDC",A22="SNDM",A22="CRS",A22="KHG",A22="EARTH"),ROUNDUP(I22/100,0),"")) | N22: =INDEX(Rates!$J$5:$J$84,MATCH(A22,Rates!$A$5:$A$84,0)) -> Waterproofing
A23: COATW | B23: =INDEX(Rates!$B$5:$B$84,MATCH(A23,Rates!$A$5:$A$84,0)) -> Polymer-modified cementitious waterproof coating (2-component) | C23: =INDEX(Rates!$C$5:$C$84,MATCH(A23,Rates!$A$5:$A$84,0)) -> kg | D23: =SUMIF(BOQ!$M$5:$M$452,A23,BOQ!$O$5:$O$452) -> 68.7715 | E23: =IFERROR(INDEX(Rates!$D$5:$D$84,MATCH(A23,Rates!$A$5:$A$84,0)),0) -> 0.05 | F23: =D23*(1+E23) -> 72.210075 | G23: =INDEX(Rates!$F$5:$F$84,MATCH(A23,Rates!$A$5:$A$84,0)) -> 5 kg | H23: =INDEX(Rates!$G$5:$G$84,MATCH(A23,Rates!$A$5:$A$84,0)) -> 5 | I23: =ROUNDUP(F23/H23,0)*H23 -> 75 | J23: =I23/H23 -> 15 | K23: =IFERROR(INDEX(Rates!$E$5:$E$84,MATCH(A23,Rates!$A$5:$A$84,0)),0) -> 450 | L23: =I23*K23 -> 33750 | M23: =IF(A23="BRK",ROUNDUP(I23/2000,0),IF(OR(A23="SNDC",A23="SNDM",A23="CRS",A23="KHG",A23="EARTH"),ROUNDUP(I23/100,0),"")) | N23: =INDEX(Rates!$J$5:$J$84,MATCH(A23,Rates!$A$5:$A$84,0)) -> Waterproofing
... A84: JBOLT | B84: =INDEX(Rates!$B$5:$B$84,MATCH(A84,Rates!$A$5:$A$84,0)) -> M12 x 250 mm galvanised J-bolt with nut and washer | C84: =INDEX(Rates!$C$5:$C$84,MATCH(A84,Rates!$A$5:$A$84,0)) -> nos | D84: =SUMIF(BOQ!$M$5:$M$452,A84,BOQ!$O$5:$O$452) -> 68 | E84: =IFERROR(INDEX(Rates!$D$5:$D$84,MATCH(A84,Rates!$A$5:$A$84,0)),0) -> 0 | F84: =D84*(1+E84) -> 68 | G84: =INDEX(Rates!$F$5:$F$84,MATCH(A84,Rates!$A$5:$A$84,0)) -> nos | H84: =INDEX(Rates!$G$5:$G$84,MATCH(A84,Rates!$A$5:$A$84,0)) -> 1 | I84: =ROUNDUP(F84/H84,0)*H84 -> 68 | J84: =I84/H84 -> 68 | K84: =IFERROR(INDEX(Rates!$E$5:$E$84,MATCH(A84,Rates!$A$5:$A$84,0)),0) -> 250 | L84: =I84*K84 -> 17000 | M84: =IF(A84="BRK",ROUNDUP(I84/2000,0),IF(OR(A84="SNDC",A84="SNDM",A84="CRS",A84="KHG",A84="EARTH"),ROUNDUP(I84/100,0),"")) | N84: =INDEX(Rates!$J$5:$J$84,MATCH(A84,Rates!$A$5:$A$84,0)) -> Solar plinths
B86: TOTAL MATERIAL COST (purchase quantities) | L86: =SUM(L5:L84) -> 9189795
B87: Covered area (sft) - GF 1,898 + FF 1,844 + mumty 362 | L87: 4104
B88: Cost per sft of covered area (PKR) | L88: =L86/L87 -> 2239.2288
B89: Total of BOQ lines before purchase rounding (incl. binding wire gross) | L89: =BOQ!T454+F11*K11 -> 9132443.6
B90: Rounding to buying units | L90: =L86-L89 -> 57351.422
B93: Cost by group
B94: Cement | L94: =SUMIF(N5:N84,B94,L5:L84) -> 2408640
B95: Bricks | L95: =SUMIF(N5:N84,B95,L5:L84) -> 2128000
B96: Steel | L96: =SUMIF(N5:N84,B96,L5:L84) -> 1967540
B97: Sand | L97: =SUMIF(N5:N84,B97,L5:L84) -> 381750
B98: Crush | L98: =SUMIF(N5:N84,B98,L5:L84) -> 440000
B99: Stone ballast | L99: =SUMIF(N5:N84,B99,L5:L84) -> 63000
B100: Earth | L100: =SUMIF(N5:N84,B100,L5:L84) -> 105000
B101: Waterproofing | L101: =SUMIF(N5:N84,B101,L5:L84) -> 498720
B102: Anti-termite | L102: =SUMIF(N5:N84,B102,L5:L84) -> 42000
B103: Roof tiles | L103: =SUMIF(N5:N84,B103,L5:L84) -> 106000
B104: Chicken mesh | L104: =SUMIF(N5:N84,B104,L5:L84) -> 105750
...

Sheet Stages
A1: Stage-wise cost and quantities to buy before each stage (gross = with wastage)
A3: Stage | B3: Stage name | C3: Material cost (PKR, before rounding) | D3: Cement (bags) | E3: Bricks (nos) | F3: Steel #2 (kg) | G3: Steel #3 (kg) | H3: Steel #4 (kg) | I3: Steel #6 (kg) | J3: Chenab sand (cft) | K3: Ravi sand (cft) | L3: Crush (cft) | M3: Khangar (cft) | N3: Earth (cft)
A4: S1 | B4: Levels and layout | C4: =SUMIF(BOQ!$A$5:$A$452,A4,BOQ!$T$5:$T$452) -> 0 | D4: =SUMIFS(BOQ!$R$5:$R$452,BOQ!$A$5:$A$452,$A4,BOQ!$M$5:$M$452,"CEM") -> 0 | E4: =SUMIFS(BOQ!$R$5:$R$452,BOQ!$A$5:$A$452,$A4,BOQ!$M$5:$M$452,"BRK") -> 0 | F4: =SUMIFS(BOQ!$R$5:$R$452,BOQ!$A$5:$A$452,$A4,BOQ!$M$5:$M$452,"ST2") -> 0 | G4: =SUMIFS(BOQ!$R$5:$R$452,BOQ!$A$5:$A$452,$A4,BOQ!$M$5:$M$452,"ST3") -> 0 | H4: =SUMIFS(BOQ!$R$5:$R$452,BOQ!$A$5:$A$452,$A4,BOQ!$M$5:$M$452,"ST4") -> 0 | I4: =SUMIFS(BOQ!$R$5:$R$452,BOQ!$A$5:$A$452,$A4,BOQ!$M$5:$M$452,"ST6") -> 0 | J4: =SUMIFS(BOQ!$R$5:$R$452,BOQ!$A$5:$A$452,$A4,BOQ!$M$5:$M$452,"SNDC") -> 0 | K4: =SUMIFS(BOQ!$R$5:$R$452,BOQ!$A$5:$A$452,$A4,BOQ!$M$5:$M$452,"SNDM") -> 0 | L4: =SUMIFS(BOQ!$R$5:$R$452,BOQ!$A$5:$A$452,$A4,BOQ!$M$5:$M$452,"CRS") -> 0 | M4: =SUMIFS(BOQ!$R$5:$R$452,BOQ!$A$5:$A$452,$A4,BOQ!$M$5:$M$452,"KHG") -> 0 | N4: =SUMIFS(BOQ!$R$5:$R$452,BOQ!$A$5:$A$452,$A4,BOQ!$M$5:$M$452,"EARTH") -> 0
A5: S2 | B5: Excavation | C5: =SUMIF(BOQ!$A$5:$A$452,A5,BOQ!$T$5:$T$452) -> 0 | D5: =SUMIFS(BOQ!$R$5:$R$452,BOQ!$A$5:$A$452,$A5,BOQ!$M$5:$M$452,"CEM") -> 0 | E5: =SUMIFS(BOQ!$R$5:$R$452,BOQ!$A$5:$A$452,$A5,BOQ!$M$5:$M$452,"BRK") -> 0 | F5: =SUMIFS(BOQ!$R$5:$R$452,BOQ!$A$5:$A$452,$A5,BOQ!$M$5:$M$452,"ST2") -> 0 | G5: =SUMIFS(BOQ!$R$5:$R$452,BOQ!$A$5:$A$452,$A5,BOQ!$M$5:$M$452,"ST3") -> 0 | H5: =SUMIFS(BOQ!$R$5:$R$452,BOQ!$A$5:$A$452,$A5,BOQ!$M$5:$M$452,"ST4") -> 0 | I5: =SUMIFS(BOQ!$R$5:$R$452,BOQ!$A$5:$A$452,$A5,BOQ!$M$5:$M$452,"ST6") -> 0 | J5: =SUMIFS(BOQ!$R$5:$R$452,BOQ!$A$5:$A$452,$A5,BOQ!$M$5:$M$452,"SNDC") -> 0 | K5: =SUMIFS(BOQ!$R$5:$R$452,BOQ!$A$5:$A$452,$A5,BOQ!$M$5:$M$452,"SNDM") -> 0 | L5: =SUMIFS(BOQ!$R$5:$R$452,BOQ!$A$5:$A$452,$A5,BOQ!$M$5:$M$452,"CRS") -> 0 | M5: =SUMIFS(BOQ!$R$5:$R$452,BOQ!$A$5:$A$452,$A5,BOQ!$M$5:$M$452,"KHG") -> 0 | N5: =SUMIFS(BOQ!$R$5:$R$452,BOQ!$A$5:$A$452,$A5,BOQ!$M$5:$M$452,"EARTH") -> 0
A6: S3 | B6: Anti-termite treatment | C6: =SUMIF(BOQ!$A$5:$A$452,A6,BOQ!$T$5:$T$452) -> 41407.327 | D6: =SUMIFS(BOQ!$R$5:$R$452,BOQ!$A$5:$A$452,$A6,BOQ!$M$5:$M$452,"CEM") -> 0 | E6: =SUMIFS(BOQ!$R$5:$R$452,BOQ!$A$5:$A$452,$A6,BOQ!$M$5:$M$452,"BRK") -> 0 | F6: =SUMIFS(BOQ!$R$5:$R$452,BOQ!$A$5:$A$452,$A6,BOQ!$M$5:$M$452,"ST2") -> 0 | G6: =SUMIFS(BOQ!$R$5:$R$452,BOQ!$A$5:$A$452,$A6,BOQ!$M$5:$M$452,"ST3") -> 0 | H6: =SUMIFS(BOQ!$R$5:$R$452,BOQ!$A$5:$A$452,$A6,BOQ!$M$5:$M$452,"ST4") -> 0 | I6: =SUMIFS(BOQ!$R$5:$R$452,BOQ!$A$5:$A$452,$A6,BOQ!$M$5:$M$452,"ST6") -> 0 | J6: =SUMIFS(BOQ!$R$5:$R$452,BOQ!$A$5:$A$452,$A6,BOQ!$M$5:$M$452,"SNDC") -> 0 | K6: =SUMIFS(BOQ!$R$5:$R$452,BOQ!$A$5:$A$452,$A6,BOQ!$M$5:$M$452,"SNDM") -> 0 | L6: =SUMIFS(BOQ!$R$5:$R$452,BOQ!$A$5:$A$452,$A6,BOQ!$M$5:$M$452,"CRS") -> 0 | M6: =SUMIFS(BOQ!$R$5:$R$452,BOQ!$A$5:$A$452,$A6,BOQ!$M$5:$M$452,"KHG") -> 0 | N6: =SUMIFS(BOQ!$R$5:$R$452,BOQ!$A$5:$A$452,$A6,BOQ!$M$5:$M$452,"EARTH") -> 0
A7: S4 | B7: Foundations | C7: =SUMIF(BOQ!$A$5:$A$452,A7,BOQ!$T$5:$T$452) -> 853543.6 | D7: =SUMIFS(BOQ!$R$5:$R$452,BOQ!$A$5:$A$452,$A7,BOQ!$M$5:$M$452,"CEM") -> 142.13506 | E7: =SUMIFS(BOQ!$R$5:$R$452,BOQ!$A$5:$A$452,$A7,BOQ!$M$5:$M$452,"BRK") -> 34314.307 | F7: =SUMIFS(BOQ!$R$5:$R$452,BOQ!$A$5:$A$452,$A7,BOQ!$M$5:$M$452,"ST2") -> 0 | G7: =SUMIFS(BOQ!$R$5:$R$452,BOQ!$A$5:$A$452,$A7,BOQ!$M$5:$M$452,"ST3") -> 0 | H7: =SUMIFS(BOQ!$R$5:$R$452,BOQ!$A$5:$A$452,$A7,BOQ!$M$5:$M$452,"ST4") -> 12.13212 | I7: =SUMIFS(BOQ!$R$5:$R$452,BOQ!$A$5:$A$452,$A7,BOQ!$M$5:$M$452,"ST6") -> 0 | J7: =SUMIFS(BOQ!$R$5:$R$452,BOQ!$A$5:$A$452,$A7,BOQ!$M$5:$M$452,"SNDC") -> 142.78658 | K7: =SUMIFS(BOQ!$R$5:$R$452,BOQ!$A$5:$A$452,$A7,BOQ!$M$5:$M$452,"SNDM") -> 894.13276 | L7: =SUMIFS(BOQ!$R$5:$R$452,BOQ!$A$5:$A$452,$A7,BOQ!$M$5:$M$452,"CRS") -> 277.64079 | M7: =SUMIFS(BOQ!$R$5:$R$452,BOQ!$A$5:$A$452,$A7,BOQ!$M$5:$M$452,"KHG") -> 0 | N7: =SUMIFS(BOQ!$R$5:$R$452,BOQ!$A$5:$A$452,$A7,BOQ!$M$5:$M$452,"EARTH") -> 0
A8: S5 | B8: Plinth beam and DPC | C8: =SUMIF(BOQ!$A$5:$A$452,A8,BOQ!$T$5:$T$452) -> 405590.32 | D8: =SUMIFS(BOQ!$R$5:$R$452,BOQ!$A$5:$A$452,$A8,BOQ!$M$5:$M$452,"CEM") -> 59.089761 | E8: =SUMIFS(BOQ!$R$5:$R$452,BOQ!$A$5:$A$452,$A8,BOQ!$M$5:$M$452,"BRK") -> 0 | F8: =SUMIFS(BOQ!$R$5:$R$452,BOQ!$A$5:$A$452,$A8,BOQ!$M$5:$M$452,"ST2") -> 81.840304 | G8: =SUMIFS(BOQ!$R$5:$R$452,BOQ!$A$5:$A$452,$A8,BOQ!$M$5:$M$452,"ST3") -> 0 | H8: =SUMIFS(BOQ!$R$5:$R$452,BOQ!$A$5:$A$452,$A8,BOQ!$M$5:$M$452,"ST4") -> 509.54852 | I8: =SUMIFS(BOQ!$R$5:$R$452,BOQ!$A$5:$A$452,$A8,BOQ!$M$5:$M$452,"ST6") -> 0 | J8: =SUMIFS(BOQ!$R$5:$R$452,BOQ!$A$5:$A$452,$A8,BOQ!$M$5:$M$452,"SNDC") -> 114.69406 | K8: =SUMIFS(BOQ!$R$5:$R$452,BOQ!$A$5:$A$452,$A8,BOQ!$M$5:$M$452,"SNDM") -> 60.302232 | L8: =SUMIFS(BOQ!$R$5:$R$452,BOQ!$A$5:$A$452,$A8,BOQ!$M$5:$M$452,"CRS") -> 223.01612 | M8: =SUMIFS(BOQ!$R$5:$R$452,BOQ!$A$5:$A$452,$A8,BOQ!$M$5:$M$452,"KHG") -> 0 | N8: =SUMIFS(BOQ!$R$5:$R$452,BOQ!$A$5:$A$452,$A8,BOQ!$M$5:$M$452,"EARTH") -> 0
A9: S6 | B9: Filling and sub-floor | C9: =SUMIF(BOQ!$A$5:$A$452,A9,BOQ!$T$5:$T$452) -> 333581.37 | D9: =SUMIFS(BOQ!$R$5:$R$452,BOQ!$A$5:$A$452,$A9,BOQ!$M$5:$M$452,"CEM") -> 45.1243 | E9: =SUMIFS(BOQ!$R$5:$R$452,BOQ!$A$5:$A$452,$A9,BOQ!$M$5:$M$452,"BRK") -> 0 | F9: =SUMIFS(BOQ!$R$5:$R$452,BOQ!$A$5:$A$452,$A9,BOQ!$M$5:$M$452,"ST2") -> 0 | G9: =SUMIFS(BOQ!$R$5:$R$452,BOQ!$A$5:$A$452,$A9,BOQ!$M$5:$M$452,"ST3") -> 0 | H9: =SUMIFS(BOQ!$R$5:$R$452,BOQ!$A$5:$A$452,$A9,BOQ!$M$5:$M$452,"ST4") -> 0 | I9: =SUMIFS(BOQ!$R$5:$R$452,BOQ!$A$5:$A$452,$A9,BOQ!$M$5:$M$452,"ST6") -> 0 | J9: =SUMIFS(BOQ!$R$5:$R$452,BOQ!$A$5:$A$452,$A9,BOQ!$M$5:$M$452,"SNDC") -> 236.57378 | K9: =SUMIFS(BOQ!$R$5:$R$452,BOQ!$A$5:$A$452,$A9,BOQ!$M$5:$M$452,"SNDM") -> 204.0512 | L9: =SUMIFS(BOQ!$R$5:$R$452,BOQ!$A$5:$A$452,$A9,BOQ!$M$5:$M$452,"CRS") -> 460.00468 | M9: =SUMIFS(BOQ!$R$5:$R$452,BOQ!$A$5:$A$452,$A9,BOQ!$M$5:$M$452,"KHG") -> 698.30859 | N9: =SUMIFS(BOQ!$R$5:$R$452,BOQ!$A$5:$A$452,$A9,BOQ!$M$5:$M$452,"EARTH") -> 4184.7993
A10: S7 | B10: Masonry | C10: =SUMIF(BOQ!$A$5:$A$452,A10,BOQ!$T$5:$T$452) -> 1697074.7 | D10: =SUMIFS(BOQ!$R$5:$R$452,BOQ!$A$5:$A$452,$A10,BOQ!$M$5:$M$452,"CEM") -> 277.27198 | E10: =SUMIFS(BOQ!$R$5:$R$452,BOQ!$A$5:$A$452,$A10,BOQ!$M$5:$M$452,"BRK") -> 74295.251 | F10: =SUMIFS(BOQ!$R$5:$R$452,BOQ!$A$5:$A$452,$A10,BOQ!$M$5:$M$452,"ST2") -> 0 | G10: =SUMIFS(BOQ!$R$5:$R$452,BOQ!$A$5:$A$452,$A10,BOQ!$M$5:$M$452,"ST3") -> 0 | H10: =SUMIFS(BOQ!$R$5:$R$452,BOQ!$A$5:$A$452,$A10,BOQ!$M$5:$M$452,"ST4") -> 0 | I10: =SUMIFS(BOQ!$R$5:$R$452,BOQ!$A$5:$A$452,$A10,BOQ!$M$5:$M$452,"ST6") -> 0 | J10: =SUMIFS(BOQ!$R$5:$R$452,BOQ!$A$5:$A$452,$A10,BOQ!$M$5:$M$452,"SNDC") -> 0 | K10: =SUMIFS(BOQ!$R$5:$R$452,BOQ!$A$5:$A$452,$A10,BOQ!$M$5:$M$452,"SNDM") -> 1895.161 | L10: =SUMIFS(BOQ!$R$5:$R$452,BOQ!$A$5:$A$452,$A10,BOQ!$M$5:$M$452,"CRS") -> 0 | M10: =SUMIFS(BOQ!$R$5:$R$452,BOQ!$A$5:$A$452,$A10,BOQ!$M$5:$M$452,"KHG") -> 0 | N10: =SUMIFS(BOQ!$R$5:$R$452,BOQ!$A$5:$A$452,$A10,BOQ!$M$5:$M$452,"EARTH") -> 0
A11: S8 | B11: RCC (superstructure) | C11: =SUMIF(BOQ!$A$5:$A$452,A11,BOQ!$T$5:$T$452) -> 2760483.5 | D11: =SUMIFS(BOQ!$R$5:$R$452,BOQ!$A$5:$A$452,$A11,BOQ!$M$5:$M$452,"CEM") -> 455.19892 | E11: =SUMIFS(BOQ!$R$5:$R$452,BOQ!$A$5:$A$452,$A11,BOQ!$M$5:$M$452,"BRK") -> 1422.3283 | F11: =SUMIFS(BOQ!$R$5:$R$452,BOQ!$A$5:$A$452,$A11,BOQ!$M$5:$M$452,"ST2") -> 27.969032 | G11: =SUMIFS(BOQ!$R$5:$R$452,BOQ!$A$5:$A$452,$A11,BOQ!$M$5:$M$452,"ST3") -> 3477.4881 | H11: =SUMIFS(BOQ!$R$5:$R$452,BOQ!$A$5:$A$452,$A11,BOQ!$M$5:$M$452,"ST4") -> 1729.9538 | I11: =SUMIFS(BOQ!$R$5:$R$452,BOQ!$A$5:$A$452,$A11,BOQ!$M$5:$M$452,"ST6") -> 1013.5763 | J11: =SUMIFS(BOQ!$R$5:$R$452,BOQ!$A$5:$A$452,$A11,BOQ!$M$5:$M$452,"SNDC") -> 1274.8627 | K11: =SUMIFS(BOQ!$R$5:$R$452,BOQ!$A$5:$A$452,$A11,BOQ!$M$5:$M$452,"SNDM") -> 52.945488 | L11: =SUMIFS(BOQ!$R$5:$R$452,BOQ!$A$5:$A$452,$A11,BOQ!$M$5:$M$452,"CRS") -> 2478.9004 | M11: =SUMIFS(BOQ!$R$5:$R$452,BOQ!$A$5:$A$452,$A11,BOQ!$M$5:$M$452,"KHG") -> 0 | N11: =SUMIFS(BOQ!$R$5:$R$452,BOQ!$A$5:$A$452,$A11,BOQ!$M$5:$M$452,"EARTH") -> 0
A12: S9 | B12: Roof waterproofing and tiles | C12: =SUMIF(BOQ!$A$5:$A$452,A12,BOQ!$T$5:$T$452) -> 561331.22 | D12: =SUMIFS(BOQ!$R$5:$R$452,BOQ!$A$5:$A$452,$A12,BOQ!$M$5:$M$452,"CEM") -> 116.98658 | E12: =SUMIFS(BOQ!$R$5:$R$452,BOQ!$A$5:$A$452,$A12,BOQ!$M$5:$M$452,"BRK") -> 0 | F12: =SUMIFS(BOQ!$R$5:$R$452,BOQ!$A$5:$A$452,$A12,BOQ!$M$5:$M$452,"ST2") -> 0 | G12: =SUMIFS(BOQ!$R$5:$R$452,BOQ!$A$5:$A$452,$A12,BOQ!$M$5:$M$452,"ST3") -> 0 | H12: =SUMIFS(BOQ!$R$5:$R$452,BOQ!$A$5:$A$452,$A12,BOQ!$M$5:$M$452,"ST4") -> 0 | I12: =SUMIFS(BOQ!$R$5:$R$452,BOQ!$A$5:$A$452,$A12,BOQ!$M$5:$M$452,"ST6") -> 0 | J12: =SUMIFS(BOQ!$R$5:$R$452,BOQ!$A$5:$A$452,$A12,BOQ!$M$5:$M$452,"SNDC") -> 451.96661 | K12: =SUMIFS(BOQ!$R$5:$R$452,BOQ!$A$5:$A$452,$A12,BOQ!$M$5:$M$452,"SNDM") -> 155.86139 | L12: =SUMIFS(BOQ!$R$5:$R$452,BOQ!$A$5:$A$452,$A12,BOQ!$M$5:$M$452,"CRS") -> 0 | M12: =SUMIFS(BOQ!$R$5:$R$452,BOQ!$A$5:$A$452,$A12,BOQ!$M$5:$M$452,"KHG") -> 0 | N12: =SUMIFS(BOQ!$R$5:$R$452,BOQ!$A$5:$A$452,$A12,BOQ!$M$5:$M$452,"EARTH") -> 0
A13: S10 | B13: Chicken mesh and plaster | C13: =SUMIF(BOQ!$A$5:$A$452,A13,BOQ!$T$5:$T$452) -> 509522.38 | D13: =SUMIFS(BOQ!$R$5:$R$452,BOQ!$A$5:$A$452,$A13,BOQ!$M$5:$M$452,"CEM") -> 230.52317 | E13: =SUMIFS(BOQ!$R$5:$R$452,BOQ!$A$5:$A$452,$A13,BOQ!$M$5:$M$452,"BRK") -> 0 | F13: =SUMIFS(BOQ!$R$5:$R$452,BOQ!$A$5:$A$452,$A13,BOQ!$M$5:$M$452,"ST2") -> 0 | G13: =SUMIFS(BOQ!$R$5:$R$452,BOQ!$A$5:$A$452,$A13,BOQ!$M$5:$M$452,"ST3") -> 0 | H13: =SUMIFS(BOQ!$R$5:$R$452,BOQ!$A$5:$A$452,$A13,BOQ!$M$5:$M$452,"ST4") -> 0 | I13: =SUMIFS(BOQ!$R$5:$R$452,BOQ!$A$5:$A$452,$A13,BOQ!$M$5:$M$452,"ST6") -> 0 | J13: =SUMIFS(BOQ!$R$5:$R$452,BOQ!$A$5:$A$452,$A13,BOQ!$M$5:$M$452,"SNDC") -> 0 | K13: =SUMIFS(BOQ!$R$5:$R$452,BOQ!$A$5:$A$452,$A13,BOQ!$M$5:$M$452,"SNDM") -> 1205.1905 | L13: =SUMIFS(BOQ!$R$5:$R$452,BOQ!$A$5:$A$452,$A13,BOQ!$M$5:$M$452,"CRS") -> 0 | M13: =SUMIFS(BOQ!$R$5:$R$452,BOQ!$A$5:$A$452,$A13,BOQ!$M$5:$M$452,"KHG") -> 0 | N13: =SUMIFS(BOQ!$R$5:$R$452,BOQ!$A$5:$A$452,$A13,BOQ!$M$5:$M$452,"EARTH") -> 0
